Workbook

Sheet Exec Summ
C3: EXECUTIVE SUMMARY | L3: ='Exec Summ'!$F$6 -> Hudson View Park
D5: DEAL SUMMARY
D6: Property Name | F6: =OneLineRR!C67 -> Hudson View Park | G6: Financing:
D7: Street Address | F7: =OneLineRR!C68 -> 29 Hudson View Drive | G7: LTV | H7: 0.65
D8: City, State Zip | F8: =OneLineRR!C69 -> Beacon, NY 12508 | G8: Rate | H8: 0.055
D9: Rentable SF | F9: ='Unit Mix'!G74 -> 0 | G9: Amort. | H9: 30
D10: Total Units | E10: =COUNTIF(D40:D44,"*") -> 0 | F10: ='Unit Mix'!G70 -> 0 | G10: Interest Only | H10: No
D11: In-Place Occupancy | F11: ='Unit Mix'!G72 -> #DIV/0! | G11: Amount | H11: =$G$19*H7 -> #DIV/0!
D12: Year Built | F12: 1900 | G12: Annual Pmt | H12: =IF(H10="Yes",H11*$H$8,PMT(H8/12,H9*12,-H11,0)*12) -> #DIV/0!
D13: Google Maps Link | F13: www.google.com | G13: DSCR | H13: =$E$25/H12 -> #DIV/0!
D14: CapEx Required | E14: 0 | F14: =E14*F10 -> 0 | G14: Debt Yield | H14: =E25/H11 -> #DIV/0!
D17: VALUATION SUMMARY
F18: Low | G18: Medium | H18: Target | J18: Equity Summary | N18: Round Values: | O18: Closing Costs
D19: Purchase Price | F19: =ROUND($E$25/F25,-$N$19) -> #DIV/0! | G19: =ROUND($E$25/G25,-$N$19) -> #DIV/0! | H19: =ROUND($E$25/H25,-$N$19) -> #DIV/0! | J19: Equity | K19: =$G$19+$F$14-$H$11+($G$19*$O$19) -> #DIV/0! | N19: 0 | O19: 0.03
D20: Per Unit | F20: =F19/($F$10+$E$10) -> #DIV/0! | G20: =G19/($F$10+$E$10) -> #DIV/0! | H20: =H19/($F$10+$E$10) -> #DIV/0! | J20: In-Place CoC | K20: =+(E25-$H$12)/$K$19 -> #DIV/0!
D21: Per SF | F21: =F19/$F$9 -> #DIV/0! | G21: =G19/$F$9 -> #DIV/0! | H21: =H19/$F$9 -> #DIV/0! | J21: Stabilized CoC | K21: =+(E26-$H$12)/$K$19 -> #DIV/0!
E23: NOI | F23: Cap Rates | J23: ="*Includes $"&TEXT($F$14,"$0.0")/1000000&"M in capex and "&TEXT($O$19,"0.0%")&" closing costs" -> *Includes $0M in capex and 3.0% closing costs
D24: T12 | E24: ='P&Ls Summary'!I40 -> 6299663.2 | F24: =$E24/F$19 -> #DIV/0! | G24: =$E24/G$19 -> #DIV/0! | H24: =$E24/H$19 -> #DIV/0! | N24: Cap Increments:
D25: In-Place | E25: ='P&Ls Summary'!S40 -> #DIV/0! | F25: =G25+N25 -> 0.06 | G25: 0.0575 | H25: =G25-N25 -> 0.055 | N25: 0.0025
D26: Stabilized | E26: ='P&Ls Summary'!V40 -> #DIV/0! | F26: =$E26/F$19 -> #DIV/0! | G26: =$E26/G$19 -> #DIV/0! | H26: =$E26/H$19 -> #DIV/0!
D28: UNIT MIX SUMMARY
D29: Unit Type | E29: # Units | F29: % of Unit Mix | G29: Sq Ft | H29: Min Rent | I29: Max Rent | J29: In-Place Rent | K29: Market Rent | N29: **Enter Market Rents on 'Unit Mix' tab
D30: Studio | E30: =SUMIFS('Unit Mix'!$F$6:$F$62,'Unit Mix'!$AI$6:$AI$62,'Exec Summ'!D30) -> 0 | F30: =E30/$E$35 -> #DIV/0! | G30: =SUMIFS('Unit Mix'!$G$6:$G$62,'Unit Mix'!$AI$6:$AI$62,'Exec Summ'!D30)/E30 -> #DIV/0! | H30: =_xlfn.MINIFS('Unit Mix'!U$6:U$62,'Unit Mix'!$AI$6:$AI$62,'Exec Summ'!$D30) -> 0 | I30: =_xlfn.MAXIFS('Unit Mix'!V$6:V$62,'Unit Mix'!$AI$6:$AI$62,'Exec Summ'!$D30) -> 0 | J30: =SUMIFS('Unit Mix'!$I$6:$I$62,'Unit Mix'!$AI$6:$AI$62,'Exec Summ'!D30)/E30 -> #DIV/0! | K30: =SUMIFS('Unit Mix'!$O$6:$O$62,'Unit Mix'!$AI$6:$AI$62,'Exec Summ'!D30)/E30 -> #DIV/0!
D31: 1BR | E31: =SUMIFS('Unit Mix'!$F$6:$F$62,'Unit Mix'!$AI$6:$AI$62,'Exec Summ'!D31) -> 0 | F31: =E31/$E$35 -> #DIV/0! | G31: =SUMIFS('Unit Mix'!$G$6:$G$62,'Unit Mix'!$AI$6:$AI$62,'Exec Summ'!D31)/E31 -> #DIV/0! | H31: =_xlfn.MINIFS('Unit Mix'!U$6:U$62,'Unit Mix'!$AI$6:$AI$62,'Exec Summ'!$D31) -> 0 | I31: =_xlfn.MAXIFS('Unit Mix'!V$6:V$62,'Unit Mix'!$AI$6:$AI$62,'Exec Summ'!$D31) -> 0 | J31: =SUMIFS('Unit Mix'!$I$6:$I$62,'Unit Mix'!$AI$6:$AI$62,'Exec Summ'!D31)/E31 -> #DIV/0! | K31: =SUMIFS('Unit Mix'!$O$6:$O$62,'Unit Mix'!$AI$6:$AI$62,'Exec Summ'!D31)/E31 -> #DIV/0!
D32: 2BR | E32: =SUMIFS('Unit Mix'!$F$6:$F$62,'Unit Mix'!$AI$6:$AI$62,'Exec Summ'!D32) -> 0 | F32: =E32/$E$35 -> #DIV/0! | G32: =SUMIFS('Unit Mix'!$G$6:$G$62,'Unit Mix'!$AI$6:$AI$62,'Exec Summ'!D32)/E32 -> #DIV/0! | H32: =_xlfn.MINIFS('Unit Mix'!U$6:U$62,'Unit Mix'!$AI$6:$AI$62,'Exec Summ'!$D32) -> 0 | I32: =_xlfn.MAXIFS('Unit Mix'!V$6:V$62,'Unit Mix'!$AI$6:$AI$62,'Exec Summ'!$D32) -> 0 | J32: =SUMIFS('Unit Mix'!$I$6:$I$62,'Unit Mix'!$AI$6:$AI$62,'Exec Summ'!D32)/E32 -> #DIV/0! | K32: =SUMIFS('Unit Mix'!$O$6:$O$62,'Unit Mix'!$AI$6:$AI$62,'Exec Summ'!D32)/E32 -> #DIV/0!
D33: 3BR | E33: =SUMIFS('Unit Mix'!$F$6:$F$62,'Unit Mix'!$AI$6:$AI$62,'Exec Summ'!D33) -> 0 | F33: =E33/$E$35 -> #DIV/0! | G33: =SUMIFS('Unit Mix'!$G$6:$G$62,'Unit Mix'!$AI$6:$AI$62,'Exec Summ'!D33)/E33 -> #DIV/0! | H33: =_xlfn.MINIFS('Unit Mix'!U$6:U$62,'Unit Mix'!$AI$6:$AI$62,'Exec Summ'!$D33) -> 0 | I33: =_xlfn.MAXIFS('Unit Mix'!V$6:V$62,'Unit Mix'!$AI$6:$AI$62,'Exec Summ'!$D33) -> 0 | J33: =SUMIFS('Unit Mix'!$I$6:$I$62,'Unit Mix'!$AI$6:$AI$62,'Exec Summ'!D33)/E33 -> #DIV/0! | K33: =SUMIFS('Unit Mix'!$O$6:$O$62,'Unit Mix'!$AI$6:$AI$62,'Exec Summ'!D33)/E33 -> #DIV/0!
D34: 4BR | E34: =SUMIFS('Unit Mix'!$F$6:$F$62,'Unit Mix'!$AI$6:$AI$62,'Exec Summ'!D34) -> 0 | F34: =E34/$E$35 -> #DIV/0! | G34: =SUMIFS('Unit Mix'!$G$6:$G$62,'Unit Mix'!$AI$6:$AI$62,'Exec Summ'!D34)/E34 -> #DIV/0! | H34: =_xlfn.MINIFS('Unit Mix'!U$6:U$62,'Unit Mix'!$AI$6:$AI$62,'Exec Summ'!$D34) -> 0 | I34: =_xlfn.MAXIFS('Unit Mix'!V$6:V$62,'Unit Mix'!$AI$6:$AI$62,'Exec Summ'!$D34) -> 0 | J34: =SUMIFS('Unit Mix'!$I$6:$I$62,'Unit Mix'!$AI$6:$AI$62,'Exec Summ'!D34)/E34 -> #DIV/0! | K34: =SUMIFS('Unit Mix'!$O$6:$O$62,'Unit Mix'!$AI$6:$AI$62,'Exec Summ'!D34)/E34 -> #DIV/0!
D35: Total | E35: =SUM(E30:E34) -> 0 | F35: =SUM(F30:F34) -> #DIV/0! | G35: =SUMPRODUCT(G30:G34,$E$30:$E$34) -> #DIV/0! | J35: =SUMPRODUCT(J30:J34,$E$30:$E$34) -> #DIV/0! | K35: =SUMPRODUCT(K30:K34,$E$30:$E$34) -> #DIV/0! | N35: =J35='Rent Roll'!M516+'Rent Roll'!N516 -> #DIV/0! | O35: =K35='Rent Roll'!P516 -> #DIV/0!
D36: Wtd Average | G36: =SUMPRODUCT(G30:G34,$E$30:$E$34)/$E$35 -> #DIV/0! | J36: =SUMPRODUCT(J30:J34,$E$30:$E$34)/$E$35 -> #DIV/0! | K36: =SUMPRODUCT(K30:K34,$E$30:$E$34)/$E$35 -> #DIV/0! | N36: =J36='Unit Mix'!J63 -> #DIV/0! | O36: =K36='Unit Mix'!P63 -> #DIV/0!
D38: COMMERCIAL UNIT SUMMARY
D39: Unit | E39: Tenant | F39: Sq Ft | G39: Lease Term | H39: Lease Start | I39: Lease Exp | J39: In-Place Rent | K39: Market Rent
N40: [Link to source file]
D45: Total | J45: =SUM(J40:J44) -> 0 | K45: =SUM(K40:K44) -> 0

Sheet P&Ls Summary
B3: 0 | C3: INCOME STATEMENT SUMMARY | Y3: ='Exec Summ'!$F$6 -> Hudson View Park | AA3: ='Exec Summ'!$F$10+'Exec Summ'!$E$10 -> 0 | AB3: =IF(COUNTIF(H61:V63,"False")=0,"OK","ERROR") -> OK
D4: Choose if columns included in OM/BOV---> | H4: EXCLUDE FROM OM | O4: EXCLUDE FROM OM | R4: INCLUDE IN OM | U4: INCLUDE IN OM | AA4: Options for Assumptions
E5: ='P&Ls Detailed'!T5 -> YE 2022 | F5: ='P&Ls Detailed'!U5 -> YE 2023 | G5: ='P&Ls Detailed'!V5 -> YE 2024 | H5: ='P&Ls Detailed'!W5 -> T-12 (05.24-04.25) | J5: ='P&Ls Detailed'!X5 -> T-9 Ann. (08.24-04.25) | K5: ='P&Ls Detailed'!Y5 -> T-6 Ann. (11.24-04.25) | L5: ='P&Ls Detailed'!Z5 -> T-3 Ann. (02.25-04.25) | M5: ='P&Ls Detailed'!AA5 -> T-1 Ann. (04.25-04.25) | O5: ADJUSTED T12 | R5: IN-PLACE | U5: STABILIZED | X5: PROFORMA NOTES | AA5: 0 | AB5: Client | AC5: Choose | AD5: UW Assumption
H6: PER UNIT | I6: TOTAL | O6: PER UNIT | P6: TOTAL | R6: PER UNIT | S6: TOTAL | U6: PER UNIT | V6: TOTAL
AA7: Numbers Are Per Unit
D8: Income | AA8: 1 | AB8: 2 | AC8: --> # to Choose UW Assumption
D9: Market Rent | H9: =I9/$AA$3 -> #DIV/0! | I9: =SUMIFS('P&Ls Detailed'!W:W,'P&Ls Detailed'!$E:$E,'P&Ls Summary'!$D9,'P&Ls Detailed'!$D:$D,'P&Ls Summary'!$Y$3) -> 12277197 | J9: =SUMIFS('P&Ls Detailed'!X:X,'P&Ls Detailed'!$E:$E,'P&Ls Summary'!$D9,'P&Ls Detailed'!$D:$D,'P&Ls Summary'!$Y$3) -> 12312906 | K9: =SUMIFS('P&Ls Detailed'!Y:Y,'P&Ls Detailed'!$E:$E,'P&Ls Summary'!$D9,'P&Ls Detailed'!$D:$D,'P&Ls Summary'!$Y$3) -> 12332018 | L9: =SUMIFS('P&Ls Detailed'!Z:Z,'P&Ls Detailed'!$E:$E,'P&Ls Summary'!$D9,'P&Ls Detailed'!$D:$D,'P&Ls Summary'!$Y$3) -> 12350082 | M9: =SUMIFS('P&Ls Detailed'!AA:AA,'P&Ls Detailed'!$E:$E,'P&Ls Summary'!$D9,'P&Ls Detailed'!$D:$D,'P&Ls Summary'!$Y$3) -> 12369476 | R9: =S9/$AA$3 -> #DIV/0! | S9: ='Exec Summ'!K36*'Exec Summ'!E35*12 -> #DIV/0! | U9: =V9/$AA$3 -> #DIV/0! | V9: =S9*(1+$V$42) -> #DIV/0! | X9: See Unit Mix
D10: Loss to Lease | H10: =I10/$AA$3 -> #DIV/0! | I10: =SUMIFS('P&Ls Detailed'!W:W,'P&Ls Detailed'!$E:$E,'P&Ls Summary'!$D10,'P&Ls Detailed'!$D:$D,'P&Ls Summary'!$Y$3) -> -804454.39 | J10: =SUMIFS('P&Ls Detailed'!X:X,'P&Ls Detailed'!$E:$E,'P&Ls Summary'!$D10,'P&Ls Detailed'!$D:$D,'P&Ls Summary'!$Y$3) -> -672299.33 | K10: =SUMIFS('P&Ls Detailed'!Y:Y,'P&Ls Detailed'!$E:$E,'P&Ls Summary'!$D10,'P&Ls Detailed'!$D:$D,'P&Ls Summary'!$Y$3) -> -531451.14 | L10: =SUMIFS('P&Ls Detailed'!Z:Z,'P&Ls Detailed'!$E:$E,'P&Ls Summary'!$D10,'P&Ls Detailed'!$D:$D,'P&Ls Summary'!$Y$3) -> -418531.12 | M10: =SUMIFS('P&Ls Detailed'!AA:AA,'P&Ls Detailed'!$E:$E,'P&Ls Summary'!$D10,'P&Ls Detailed'!$D:$D,'P&Ls Summary'!$Y$3) -> -344011.92 | R10: =S10/$AA$3 -> #DIV/0! | S10: =S11-S9 -> #DIV/0! | U10: =V10/$AA$3 -> #DIV/0! | V10: =-$AC$10*V9 -> #DIV/0! | X10: Market Rents Less Gross Rents | AA10: =O10*(1+$AA$5) -> 0 | AB10: =IFERROR(S10/$AA$3,"n/a") -> n/a
D11: Gross Rental Income | H11: =I11/$AA$3 -> #DIV/0! | I11: =SUM(I9:I10) -> 11472742 | J11: =SUM(J9:J10) -> 11640607 | K11: =SUM(K9:K10) -> 11800566 | L11: =SUM(L9:L10) -> 11931551 | M11: =SUM(M9:M10) -> 12025464 | O11: =P11/$AA$3 -> #DIV/0! | P11: ='Unit Mix'!G80 -> 0 | R11: =S11/$AA$3 -> #DIV/0! | S11: =('Rent Roll'!M516+'Rent Roll'!N516)*12*(1+$S$42) -> 0 | U11: =V11/$AA$3 -> #DIV/0! | V11: =SUM(V9:V10) -> #DIV/0!
D12: Less Vacancy | H12: =I12/$AA$3 -> #DIV/0! | I12: =SUMIFS('P&Ls Detailed'!W:W,'P&Ls Detailed'!$E:$E,'P&Ls Summary'!$D12,'P&Ls Detailed'!$D:$D,'P&Ls Summary'!$Y$3) -> -193440.85 | J12: =SUMIFS('P&Ls Detailed'!X:X,'P&Ls Detailed'!$E:$E,'P&Ls Summary'!$D12,'P&Ls Detailed'!$D:$D,'P&Ls Summary'!$Y$3) -> -181087.95 | K12: =SUMIFS('P&Ls Detailed'!Y:Y,'P&Ls Detailed'!$E:$E,'P&Ls Summary'!$D12,'P&Ls Detailed'!$D:$D,'P&Ls Summary'!$Y$3) -> -178731.9 | L12: =SUMIFS('P&Ls Detailed'!Z:Z,'P&Ls Detailed'!$E:$E,'P&Ls Summary'!$D12,'P&Ls Detailed'!$D:$D,'P&Ls Summary'!$Y$3) -> -126680 | M12: =SUMIFS('P&Ls Detailed'!AA:AA,'P&Ls Detailed'!$E:$E,'P&Ls Summary'!$D12,'P&Ls Detailed'!$D:$D,'P&Ls Summary'!$Y$3) -> -96843.96 | O12: =P12/$AA$3 -> #DIV/0! | P12: =SUMIFS('P&Ls Detailed'!W:W,'P&Ls Detailed'!$E:$E,'P&Ls Summary'!$D12,'P&Ls Detailed'!$D:$D,'P&Ls Summary'!$Y$3)-SUMIFS('P&Ls Detailed'!W:W,'P&Ls Detailed'!$E:$E,'P&Ls Summary'!$D12,'P&Ls Detailed'!$D:$D,'P&Ls Summary'!$Y$3,'P&Ls Detailed'!$F:$F,"Exclude") -> 0 | R12: =S12/$AA$3 -> #DIV/0! | S12: =-$S$11*AC12 -> 0 | U12: =V12/$AA$3 -> #DIV/0! | V12: =-$V$11*AC12 -> #DIV/0! | X12: =TEXT(AC12,"#0.0%")&" of Gross Rental Income" -> 3.0% of Gross Rental Income | AA12: =O12*(1+$AA$5) -> #DIV/0! | AB12: =IFERROR(S12/$AA$3,"n/a") -> n/a | AC12: 0.03 | AE12: --> Default to 3.0%
D13: Less: Concessions | H13: =I13/$AA$3 -> #DIV/0! | I13: =SUMIFS('P&Ls Detailed'!W:W,'P&Ls Detailed'!$E:$E,'P&Ls Summary'!$D13,'P&Ls Detailed'!$D:$D,'P&Ls Summary'!$Y$3) -> -67386.31 | J13: =SUMIFS('P&Ls Detailed'!X:X,'P&Ls Detailed'!$E:$E,'P&Ls Summary'!$D13,'P&Ls Detailed'!$D:$D,'P&Ls Summary'!$Y$3) -> -68301.6 | K13: =SUMIFS('P&Ls Detailed'!Y:Y,'P&Ls Detailed'!$E:$E,'P&Ls Summary'!$D13,'P&Ls Detailed'!$D:$D,'P&Ls Summary'!$Y$3) -> -69410.44 | L13: =SUMIFS('P&Ls Detailed'!Z:Z,'P&Ls Detailed'!$E:$E,'P&Ls Summary'!$D13,'P&Ls Detailed'!$D:$D,'P&Ls Summary'!$Y$3) -> -71905.44 | M13: =SUMIFS('P&Ls Detailed'!AA:AA,'P&Ls Detailed'!$E:$E,'P&Ls Summary'!$D13,'P&Ls Detailed'!$D:$D,'P&Ls Summary'!$Y$3) -> -71905.44 | O13: =P13/$AA$3 -> #DIV/0! | P13: =SUMIFS('P&Ls Detailed'!W:W,'P&Ls Detailed'!$E:$E,'P&Ls Summary'!$D13,'P&Ls Detailed'!$D:$D,'P&Ls Summary'!$Y$3)-SUMIFS('P&Ls Detailed'!W:W,'P&Ls Detailed'!$E:$E,'P&Ls Summary'!$D13,'P&Ls Detailed'!$D:$D,'P&Ls Summary'!$Y$3,'P&Ls Detailed'!$F:$F,"Exclude") -> 0 | R13: =S13/$AA$3 -> #DIV/0! | S13: =-$S$11*AC13 -> 0 | U13: =V13/$AA$3 -> #DIV/0! | V13: =-$V$11*AC13 -> #DIV/0! | X13: =TEXT(AC13,"#0.0%")&" of Gross Rental Income" -> 0.0% of Gross Rental Income | AA13: =O13*(1+$AA$5) -> #DIV/0! | AB13: =IFERROR(S13/$AA$3,"n/a") -> n/a | AC13: 0
D14: Less: Bad Debt/Collection | H14: =I14/$AA$3 -> #DIV/0! | I14: =SUMIFS('P&Ls Detailed'!W:W,'P&Ls Detailed'!$E:$E,'P&Ls Summary'!$D14,'P&Ls Detailed'!$D:$D,'P&Ls Summary'!$Y$3) -> -280.89 | J14: =SUMIFS('P&Ls Detailed'!X:X,'P&Ls Detailed'!$E:$E,'P&Ls Summary'!$D14,'P&Ls Detailed'!$D:$D,'P&Ls Summary'!$Y$3) -> -675.61333 | K14: =SUMIFS('P&Ls Detailed'!Y:Y,'P&Ls Detailed'!$E:$E,'P&Ls Summary'!$D14,'P&Ls Detailed'!$D:$D,'P&Ls Summary'!$Y$3) -> -1013.42 | L14: =SUMIFS('P&Ls Detailed'!Z:Z,'P&Ls Detailed'!$E:$E,'P&Ls Summary'!$D14,'P&Ls Detailed'!$D:$D,'P&Ls Summary'!$Y$3) -> 1780.92 | M14: =SUMIFS('P&Ls Detailed'!AA:AA,'P&Ls Detailed'!$E:$E,'P&Ls Summary'!$D14,'P&Ls Detailed'!$D:$D,'P&Ls Summary'!$Y$3) -> 0 | O14: =P14/$AA$3 -> #DIV/0! | P14: =SUMIFS('P&Ls Detailed'!W:W,'P&Ls Detailed'!$E:$E,'P&Ls Summary'!$D14,'P&Ls Detailed'!$D:$D,'P&Ls Summary'!$Y$3)-SUMIFS('P&Ls Detailed'!W:W,'P&Ls Detailed'!$E:$E,'P&Ls Summary'!$D14,'P&Ls Detailed'!$D:$D,'P&Ls Summary'!$Y$3,'P&Ls Detailed'!$F:$F,"Exclude") -> 0 | R14: =S14/$AA$3 -> #DIV/0! | S14: =-$S$11*AC14 -> 0 | U14: =V14/$AA$3 -> #DIV/0! | V14: =-$V$11*AC14 -> #DIV/0! | X14: =TEXT(AC14,"#0.0%")&" of Gross Rental Income" -> 0.0% of Gross Rental Income | AA14: =O14*(1+$AA$5) -> #DIV/0! | AB14: =IFERROR(S14/$AA$3,"n/a") -> n/a | AC14: 0
D15: Pet Income | H15: =I15/$AA$3 -> #DIV/0! | I15: =SUMIFS('P&Ls Detailed'!W:W,'P&Ls Detailed'!$E:$E,'P&Ls Summary'!$D15,'P&Ls Detailed'!$D:$D,'P&Ls Summary'!$Y$3) -> 87864.1 | J15: =SUMIFS('P&Ls Detailed'!X:X,'P&Ls Detailed'!$E:$E,'P&Ls Summary'!$D15,'P&Ls Detailed'!$D:$D,'P&Ls Summary'!$Y$3) -> 86877.08 | K15: =SUMIFS('P&Ls Detailed'!Y:Y,'P&Ls Detailed'!$E:$E,'P&Ls Summary'!$D15,'P&Ls Detailed'!$D:$D,'P&Ls Summary'!$Y$3) -> 83124.8 | L15: =SUMIFS('P&Ls Detailed'!Z:Z,'P&Ls Detailed'!$E:$E,'P&Ls Summary'!$D15,'P&Ls Detailed'!$D:$D,'P&Ls Summary'!$Y$3) -> 81165.12 | M15: =SUMIFS('P&Ls Detailed'!AA:AA,'P&Ls Detailed'!$E:$E,'P&Ls Summary'!$D15,'P&Ls Detailed'!$D:$D,'P&Ls Summary'!$Y$3) -> 76110 | O15: =P15/$AA$3 -> #DIV/0! | P15: =SUMIFS('P&Ls Detailed'!W:W,'P&Ls Detailed'!$E:$E,'P&Ls Summary'!$D15,'P&Ls Detailed'!$D:$D,'P&Ls Summary'!$Y$3)-SUMIFS('P&Ls Detailed'!W:W,'P&Ls Detailed'!$E:$E,'P&Ls Summary'!$D15,'P&Ls Detailed'!$D:$D,'P&Ls Summary'!$Y$3,'P&Ls Detailed'!$F:$F,"Exclude") -> 87864.1 | R15: =AD15 -> #DIV/0! | S15: =R15*$AA$3 -> #DIV/0! | U15: =V15/$AA$3 -> #DIV/0! | V15: =S15*(1+$V$43) -> #DIV/0! | X15: =IF(AC15=1, IF(AND($AA$5=0,AC15=1),"T12","T12 + "&TEXT($AA$5,"0.0%")),TEXT(AB15,"$##,##0")&"/unit") -> T12 | AA15: =O15*(1+$AA$5) -> #DIV/0! | AB15: 0 | AC15: 1 | AD15: =CHOOSE(AC15,AA15,AB15) -> #DIV/0!
D16: Laundry Income | H16: =I16/$AA$3 -> #DIV/0! | I16: =SUMIFS('P&Ls Detailed'!W:W,'P&Ls Detailed'!$E:$E,'P&Ls Summary'!$D16,'P&Ls Detailed'!$D:$D,'P&Ls Summary'!$Y$3) -> 133399.46 | J16: =SUMIFS('P&Ls Detailed'!X:X,'P&Ls Detailed'!$E:$E,'P&Ls Summary'!$D16,'P&Ls Detailed'!$D:$D,'P&Ls Summary'!$Y$3) -> 134801.48 | K16: =SUMIFS('P&Ls Detailed'!Y:Y,'P&Ls Detailed'!$E:$E,'P&Ls Summary'!$D16,'P&Ls Detailed'!$D:$D,'P&Ls Summary'!$Y$3) -> 134453.06 | L16: =SUMIFS('P&Ls Detailed'!Z:Z,'P&Ls Detailed'!$E:$E,'P&Ls Summary'!$D16,'P&Ls Detailed'!$D:$D,'P&Ls Summary'!$Y$3) -> 140316.32 | M16: =SUMIFS('P&Ls Detailed'!AA:AA,'P&Ls Detailed'!$E:$E,'P&Ls Summary'!$D16,'P&Ls Detailed'!$D:$D,'P&Ls Summary'!$Y$3) -> 132407.76 | O16: =P16/$AA$3 -> #DIV/0! | P16: =SUMIFS('P&Ls Detailed'!W:W,'P&Ls Detailed'!$E:$E,'P&Ls Summary'!$D16,'P&Ls Detailed'!$D:$D,'P&Ls Summary'!$Y$3)-SUMIFS('P&Ls Detailed'!W:W,'P&Ls Detailed'!$E:$E,'P&Ls Summary'!$D16,'P&Ls Detailed'!$D:$D,'P&Ls Summary'!$Y$3,'P&Ls Detailed'!$F:$F,"Exclude") -> 133399.46 | R16: =AD16 -> #DIV/0! | S16: =R16*$AA$3 -> #DIV/0! | U16: =V16/$AA$3 -> #DIV/0! | V16: =S16*(1+$V$43) -> #DIV/0! | X16: =IF(AC16=1, IF(AND($AA$5=0,AC16=1),"T12","T12 + "&TEXT($AA$5,"0.0%")),TEXT(AB16,"$##,##0")&"/unit") -> T12 | AA16: =O16*(1+$AA$5) -> #DIV/0! | AB16: 0 | AC16: 1 | AD16: =CHOOSE(AC16,AA16,AB16) -> #DIV/0!
D17: Parking Income | H17: =I17/$AA$3 -> #DIV/0! | I17: =SUMIFS('P&Ls Detailed'!W:W,'P&Ls Detailed'!$E:$E,'P&Ls Summary'!$D17,'P&Ls Detailed'!$D:$D,'P&Ls Summary'!$Y$3) -> 0 | J17: =SUMIFS('P&Ls Detailed'!X:X,'P&Ls Detailed'!$E:$E,'P&Ls Summary'!$D17,'P&Ls Detailed'!$D:$D,'P&Ls Summary'!$Y$3) -> 0 | K17: =SUMIFS('P&Ls Detailed'!Y:Y,'P&Ls Detailed'!$E:$E,'P&Ls Summary'!$D17,'P&Ls Detailed'!$D:$D,'P&Ls Summary'!$Y$3) -> 0 | L17: =SUMIFS('P&Ls Detailed'!Z:Z,'P&Ls Detailed'!$E:$E,'P&Ls Summary'!$D17,'P&Ls Detailed'!$D:$D,'P&Ls Summary'!$Y$3) -> 0 | M17: =SUMIFS('P&Ls Detailed'!AA:AA,'P&Ls Detailed'!$E:$E,'P&Ls Summary'!$D17,'P&Ls Detailed'!$D:$D,'P&Ls Summary'!$Y$3) -> 0 | O17: =P17/$AA$3 -> #DIV/0! | P17: =SUMIFS('P&Ls Detailed'!W:W,'P&Ls Detailed'!$E:$E,'P&Ls Summary'!$D17,'P&Ls Detailed'!$D:$D,'P&Ls Summary'!$Y$3)-SUMIFS('P&Ls Detailed'!W:W,'P&Ls Detailed'!$E:$E,'P&Ls Summary'!$D17,'P&Ls Detailed'!$D:$D,'P&Ls Summary'!$Y$3,'P&Ls Detailed'!$F:$F,"Exclude") -> 0 | R17: =AD17 -> #DIV/0! | S17: =R17*$AA$3 -> #DIV/0! | U17: =V17/$AA$3 -> #DIV/0! | V17: =S17*(1+$V$43) -> #DIV/0! | X17: =IF(AC17=1, IF(AND($AA$5=0,AC17=1),"T12","T12 + "&TEXT($AA$5,"0.0%")),TEXT(AB17,"$##,##0")&"/unit") -> T12 | AA17: =O17*(1+$AA$5) -> #DIV/0! | AB17: 0 | AC17: 1 | AD17: =CHOOSE(AC17,AA17,AB17) -> #DIV/0!
D18: Storage Income | H18: =I18/$AA$3 -> #DIV/0! | I18: =SUMIFS('P&Ls Detailed'!W:W,'P&Ls Detailed'!$E:$E,'P&Ls Summary'!$D18,'P&Ls Detailed'!$D:$D,'P&Ls Summary'!$Y$3) -> 0 | J18: =SUMIFS('P&Ls Detailed'!X:X,'P&Ls Detailed'!$E:$E,'P&Ls Summary'!$D18,'P&Ls Detailed'!$D:$D,'P&Ls Summary'!$Y$3) -> 0 | K18: =SUMIFS('P&Ls Detailed'!Y:Y,'P&Ls Detailed'!$E:$E,'P&Ls Summary'!$D18,'P&Ls Detailed'!$D:$D,'P&Ls Summary'!$Y$3) -> 0 | L18: =SUMIFS('P&Ls Detailed'!Z:Z,'P&Ls Detailed'!$E:$E,'P&Ls Summary'!$D18,'P&Ls Detailed'!$D:$D,'P&Ls Summary'!$Y$3) -> 0 | M18: =SUMIFS('P&Ls Detailed'!AA:AA,'P&Ls Detailed'!$E:$E,'P&Ls Summary'!$D18,'P&Ls Detailed'!$D:$D,'P&Ls Summary'!$Y$3) -> 0 | O18: =P18/$AA$3 -> #DIV/0! | P18: =SUMIFS('P&Ls Detailed'!W:W,'P&Ls Detailed'!$E:$E,'P&Ls Summary'!$D18,'P&Ls Detailed'!$D:$D,'P&Ls Summary'!$Y$3)-SUMIFS('P&Ls Detailed'!W:W,'P&Ls Detailed'!$E:$E,'P&Ls Summary'!$D18,'P&Ls Detailed'!$D:$D,'P&Ls Summary'!$Y$3,'P&Ls Detailed'!$F:$F,"Exclude") -> 0 | R18: =AD18 -> #DIV/0! | S18: =R18*$AA$3 -> #DIV/0! | U18: =V18/$AA$3 -> #DIV/0! | V18: =S18*(1+$V$43) -> #DIV/0! | X18: =IF(AC18=1, IF(AND($AA$5=0,AC18=1),"T12","T12 + "&TEXT($AA$5,"0.0%")),TEXT(AB18,"$##,##0")&"/unit") -> T12 | AA18: =O18*(1+$AA$5) -> #DIV/0! | AB18: 0 | AC18: 1 | AD18: =CHOOSE(AC18,AA18,AB18) -> #DIV/0!
D19: Utility Reimbursement | H19: =I19/$AA$3 -> #DIV/0! | I19: =SUMIFS('P&Ls Detailed'!W:W,'P&Ls Detailed'!$E:$E,'P&Ls Summary'!$D19,'P&Ls Detailed'!$D:$D,'P&Ls Summary'!$Y$3) -> 17248.35 | J19: =SUMIFS('P&Ls Detailed'!X:X,'P&Ls Detailed'!$E:$E,'P&Ls Summary'!$D19,'P&Ls Detailed'!$D:$D,'P&Ls Summary'!$Y$3) -> 17379.733 | K19: =SUMIFS('P&Ls Detailed'!Y:Y,'P&Ls Detailed'!$E:$E,'P&Ls Summary'!$D19,'P&Ls Detailed'!$D:$D,'P&Ls Summary'!$Y$3) -> 17507.34 | L19: =SUMIFS('P&Ls Detailed'!Z:Z,'P&Ls Detailed'!$E:$E,'P&Ls Summary'!$D19,'P&Ls Detailed'!$D:$D,'P&Ls Summary'!$Y$3) -> 17839.2 | M19: =SUMIFS('P&Ls Detailed'!AA:AA,'P&Ls Detailed'!$E:$E,'P&Ls Summary'!$D19,'P&Ls Detailed'!$D:$D,'P&Ls Summary'!$Y$3) -> 18000 | O19: =P19/$AA$3 -> #DIV/0! | P19: =SUMIFS('P&Ls Detailed'!W:W,'P&Ls Detailed'!$E:$E,'P&Ls Summary'!$D19,'P&Ls Detailed'!$D:$D,'P&Ls Summary'!$Y$3)-SUMIFS('P&Ls Detailed'!W:W,'P&Ls Detailed'!$E:$E,'P&Ls Summary'!$D19,'P&Ls Detailed'!$D:$D,'P&Ls Summary'!$Y$3,'P&Ls Detailed'!$F:$F,"Exclude") -> 17248.35 | R19: =AD19 -> #DIV/0! | S19: =R19*$AA$3 -> #DIV/0! | U19: =V19/$AA$3 -> #DIV/0! | V19: =S19*(1+$V$43) -> #DIV/0! | X19: =IF(AC19=1, IF(AND($AA$5=0,AC19=1),"T12","T12 + "&TEXT($AA$5,"0.0%")),TEXT(AB19,"$##,##0")&"/unit") -> T12 | AA19: =O19*(1+$AA$5) -> #DIV/0! | AB19: 0 | AC19: 1 | AD19: =CHOOSE(AC19,AA19,AB19) -> #DIV/0!
D20: Other Income | H20: =I20/$AA$3 -> #DIV/0! | I20: =SUMIFS('P&Ls Detailed'!W:W,'P&Ls Detailed'!$E:$E,'P&Ls Summary'!$D20,'P&Ls Detailed'!$D:$D,'P&Ls Summary'!$Y$3) -> 367295.05 | J20: =SUMIFS('P&Ls Detailed'!X:X,'P&Ls Detailed'!$E:$E,'P&Ls Summary'!$D20,'P&Ls Detailed'!$D:$D,'P&Ls Summary'!$Y$3) -> 300617.01 | K20: =SUMIFS('P&Ls Detailed'!Y:Y,'P&Ls Detailed'!$E:$E,'P&Ls Summary'!$D20,'P&Ls Detailed'!$D:$D,'P&Ls Summary'!$Y$3) -> 244740.24 | L20: =SUMIFS('P&Ls Detailed'!Z:Z,'P&Ls Detailed'!$E:$E,'P&Ls Summary'!$D20,'P&Ls Detailed'!$D:$D,'P&Ls Summary'!$Y$3) -> 167834.28 | M20: =SUMIFS('P&Ls Detailed'!AA:AA,'P&Ls Detailed'!$E:$E,'P&Ls Summary'!$D20,'P&Ls Detailed'!$D:$D,'P&Ls Summary'!$Y$3) -> 110008.56 | O20: =P20/$AA$3 -> #DIV/0! | P20: =SUMIFS('P&Ls Detailed'!W:W,'P&Ls Detailed'!$E:$E,'P&Ls Summary'!$D20,'P&Ls Detailed'!$D:$D,'P&Ls Summary'!$Y$3)-SUMIFS('P&Ls Detailed'!W:W,'P&Ls Detailed'!$E:$E,'P&Ls Summary'!$D20,'P&Ls Detailed'!$D:$D,'P&Ls Summary'!$Y$3,'P&Ls Detailed'!$F:$F,"Exclude") -> 367295.05 | R20: =AD20 -> #DIV/0! | S20: =R20*$AA$3 -> #DIV/0! | U20: =V20/$AA$3 -> #DIV/0! | V20: =S20*(1+$V$43) -> #DIV/0! | X20: =IF(AC20=1, IF(AND($AA$5=0,AC20=1),"T12","T12 + "&TEXT($AA$5,"0.0%")),TEXT(AB20,"$##,##0")&"/unit") -> T12 | AA20: =O20*(1+$AA$5) -> #DIV/0! | AB20: 0 | AC20: 1 | AD20: =CHOOSE(AC20,AA20,AB20) -> #DIV/0!
D21: Commercial Income | H21: =I21/$AA$3 -> #DIV/0! | I21: =SUMIFS('P&Ls Detailed'!W:W,'P&Ls Detailed'!$E:$E,'P&Ls Summary'!$D21,'P&Ls Detailed'!$D:$D,'P&Ls Summary'!$Y$3) -> 0 | J21: =SUMIFS('P&Ls Detailed'!X:X,'P&Ls Detailed'!$E:$E,'P&Ls Summary'!$D21,'P&Ls Detailed'!$D:$D,'P&Ls Summary'!$Y$3) -> 0 | K21: =SUMIFS('P&Ls Detailed'!Y:Y,'P&Ls Detailed'!$E:$E,'P&Ls Summary'!$D21,'P&Ls Detailed'!$D:$D,'P&Ls Summary'!$Y$3) -> 0 | L21: =SUMIFS('P&Ls Detailed'!Z:Z,'P&Ls Detailed'!$E:$E,'P&Ls Summary'!$D21,'P&Ls Detailed'!$D:$D,'P&Ls Summary'!$Y$3) -> 0 | M21: =SUMIFS('P&Ls Detailed'!AA:AA,'P&Ls Detailed'!$E:$E,'P&Ls Summary'!$D21,'P&Ls Detailed'!$D:$D,'P&Ls Summary'!$Y$3) -> 0 | O21: =P21/$AA$3 -> #DIV/0! | P21: =SUMIFS('P&Ls Detailed'!W:W,'P&Ls Detailed'!$E:$E,'P&Ls Summary'!$D21,'P&Ls Detailed'!$D:$D,'P&Ls Summary'!$Y$3)-SUMIFS('P&Ls Detailed'!W:W,'P&Ls Detailed'!$E:$E,'P&Ls Summary'!$D21,'P&Ls Detailed'!$D:$D,'P&Ls Summary'!$Y$3,'P&Ls Detailed'!$F:$F,"Exclude") -> 0 | R21: =S21/$AA$3 -> #DIV/0! | S21: ='Exec Summ'!J45*12 -> 0 | U21: =V21/$AA$3 -> #DIV/0! | V21: ='Exec Summ'!K45*12 -> 0 | X21: See Commercial Unit Summary | AA21: =O21*(1+$AA$5) -> #DIV/0! | AB21: =IFERROR(S21/$AA$3,"n/a") -> n/a
D22: Less Commercial Vacancy | H22: =I22/$AA$3 -> #DIV/0! | I22: =SUMIFS('P&Ls Detailed'!W:W,'P&Ls Detailed'!$E:$E,'P&Ls Summary'!$D22,'P&Ls Detailed'!$D:$D,'P&Ls Summary'!$Y$3) -> 0 | J22: =SUMIFS('P&Ls Detailed'!X:X,'P&Ls Detailed'!$E:$E,'P&Ls Summary'!$D22,'P&Ls Detailed'!$D:$D,'P&Ls Summary'!$Y$3) -> 0 | K22: =SUMIFS('P&Ls Detailed'!Y:Y,'P&Ls Detailed'!$E:$E,'P&Ls Summary'!$D22,'P&Ls Detailed'!$D:$D,'P&Ls Summary'!$Y$3) -> 0 | L22: =SUMIFS('P&Ls Detailed'!Z:Z,'P&Ls Detailed'!$E:$E,'P&Ls Summary'!$D22,'P&Ls Detailed'!$D:$D,'P&Ls Summary'!$Y$3) -> 0 | M22: =SUMIFS('P&Ls Detailed'!AA:AA,'P&Ls Detailed'!$E:$E,'P&Ls Summary'!$D22,'P&Ls Detailed'!$D:$D,'P&Ls Summary'!$Y$3) -> 0 | O22: =P22/$AA$3 -> #DIV/0! | P22: =SUMIFS('P&Ls Detailed'!W:W,'P&Ls Detailed'!$E:$E,'P&Ls Summary'!$D22,'P&Ls Detailed'!$D:$D,'P&Ls Summary'!$Y$3)-SUMIFS('P&Ls Detailed'!W:W,'P&Ls Detailed'!$E:$E,'P&Ls Summary'!$D22,'P&Ls Detailed'!$D:$D,'P&Ls Summary'!$Y$3,'P&Ls Detailed'!$F:$F,"Exclude") -> 0 | R22: =S22/$AA$3 -> #DIV/0! | S22: =-$S$21*AC22 -> 0 | U22: =V22/$AA$3 -> #DIV/0! | V22: =-$V$21*AC22 -> 0 | X22: =TEXT(AC22,"#0.0%")&" of Retail Income" -> 5.0% of Retail Income | AA22: =O22*(1+$AA$5) -> #DIV/0! | AB22: =IFERROR(S22/$AA$3,"n/a") -> n/a | AC22: 0.05
D23: Effective Gross Income | E23: =SUM(E9:E22) -> 0 | F23: =SUM(F9:F22) -> 0 | G23: =SUM(G9:G22) -> 0 | H23: =I23/$AA$3 -> #DIV/0! | I23: =SUM(I11:I22) -> 11817441 | J23: =SUM(J11:J22) -> 11930217 | K23: =SUM(K11:K22) -> 12031236 | L23: =SUM(L11:L22) -> 12141901 | M23: =SUM(M11:M22) -> 12193241 | O23: =P23/$AA$3 -> #DIV/0! | P23: =SUM(P11:P22) -> 605806.96 | R23: =S23/$AA$3 -> #DIV/0! | S23: =SUM(S11:S22) -> #DIV/0! | U23: =V23/$AA$3 -> #DIV/0! | V23: =SUM(V11:V22) -> #DIV/0!
D25: Expenses
D26: Property Taxes | H26: =I26/$AA$3 -> #DIV/0! | I26: =SUMIFS('P&Ls Detailed'!W:W,'P&Ls Detailed'!$E:$E,'P&Ls Summary'!$D26,'P&Ls Detailed'!$D:$D,'P&Ls Summary'!$Y$3) -> 1218605.5 | J26: =SUMIFS('P&Ls Detailed'!X:X,'P&Ls Detailed'!$E:$E,'P&Ls Summary'!$D26,'P&Ls Detailed'!$D:$D,'P&Ls Summary'!$Y$3) -> 1229186.3 | K26: =SUMIFS('P&Ls Detailed'!Y:Y,'P&Ls Detailed'!$E:$E,'P&Ls Summary'!$D26,'P&Ls Detailed'!$D:$D,'P&Ls Summary'!$Y$3) -> 1241705.9 | L26: =SUMIFS('P&Ls Detailed'!Z:Z,'P&Ls Detailed'!$E:$E,'P&Ls Summary'!$D26,'P&Ls Detailed'!$D:$D,'P&Ls Summary'!$Y$3) -> 1260485.2 | M26: =SUMIFS('P&Ls Detailed'!AA:AA,'P&Ls Detailed'!$E:$E,'P&Ls Summary'!$D26,'P&Ls Detailed'!$D:$D,'P&Ls Summary'!$Y$3) -> 1260485.2 | O26: =P26/$AA$3 -> #DIV/0! | P26: =SUMIFS('P&Ls Detailed'!W:W,'P&Ls Detailed'!$E:$E,'P&Ls Summary'!$D26,'P&Ls Detailed'!$D:$D,'P&Ls Summary'!$Y$3)-SUMIFS('P&Ls Detailed'!W:W,'P&Ls Detailed'!$E:$E,'P&Ls Summary'!$D26,'P&Ls Detailed'!$D:$D,'P&Ls Summary'!$Y$3,'P&Ls Detailed'!$F:$F,"Exclude") -> 1218605.5 | R26: =AD26 -> #DIV/0! | S26: =R26*$AA$3 -> #DIV/0! | U26: =V26/$AA$3 -> #DIV/0! | V26: =S26*(1+$V$43) -> #DIV/0! | X26: =IF(AC26=1, IF(AND($AA$5=0,AC26=1),"T12","T12 + "&TEXT($AA$5,"0.0%")),"Actual Tax") -> T12 | AA26: =O26*(1+$AA$5) -> #DIV/0! | AB26: ='Tax-Assessor Info'!O16/'P&Ls Summary'!AA3 -> #DIV/0! | AC26: 1 | AD26: =CHOOSE(AC26,AA26,AB26) -> #DIV/0! | AE26: --> Default to prior four quarter actuals
D27: Insurance | H27: =I27/$AA$3 -> #DIV/0! | I27: =SUMIFS('P&Ls Detailed'!W:W,'P&Ls Detailed'!$E:$E,'P&Ls Summary'!$D27,'P&Ls Detailed'!$D:$D,'P&Ls Summary'!$Y$3) -> 369668.22 | J27: =SUMIFS('P&Ls Detailed'!X:X,'P&Ls Detailed'!$E:$E,'P&Ls Summary'!$D27,'P&Ls Detailed'!$D:$D,'P&Ls Summary'!$Y$3) -> 377159.95 | K27: =SUMIFS('P&Ls Detailed'!Y:Y,'P&Ls Detailed'!$E:$E,'P&Ls Summary'!$D27,'P&Ls Detailed'!$D:$D,'P&Ls Summary'!$Y$3) -> 380028.08 | L27: =SUMIFS('P&Ls Detailed'!Z:Z,'P&Ls Detailed'!$E:$E,'P&Ls Summary'!$D27,'P&Ls Detailed'!$D:$D,'P&Ls Summary'!$Y$3) -> 378922.68 | M27: =SUMIFS('P&Ls Detailed'!AA:AA,'P&Ls Detailed'!$E:$E,'P&Ls Summary'!$D27,'P&Ls Detailed'!$D:$D,'P&Ls Summary'!$Y$3) -> 378922.68 | O27: =P27/$AA$3 -> #DIV/0! | P27: =SUMIFS('P&Ls Detailed'!W:W,'P&Ls Detailed'!$E:$E,'P&Ls Summary'!$D27,'P&Ls Detailed'!$D:$D,'P&Ls Summary'!$Y$3)-SUMIFS('P&Ls Detailed'!W:W,'P&Ls Detailed'!$E:$E,'P&Ls Summary'!$D27,'P&Ls Detailed'!$D:$D,'P&Ls Summary'!$Y$3,'P&Ls Detailed'!$F:$F,"Exclude") -> 369668.22 | R27: =AD27 -> #DIV/0! | S27: =R27*$AA$3 -> #DIV/0! | U27: =V27/$AA$3 -> #DIV/0! | V27: =S27*(1+$V$43) -> #DIV/0! | X27: =IF(AC27=1, IF(AND($AA$5=0,AC27=1),"T12","T12 + "&TEXT($AA$5,"0.0%")),TEXT(AB27,"$##,##0")&"/unit") -> T12 | AA27: =O27*(1+$AA$5) -> #DIV/0! | AB27: 600 | AC27: 1 | AD27: =CHOOSE(AC27,AA27,AB27) -> #DIV/0!
D28: Utilities | H28: =I28/$AA$3 -> #DIV/0! | I28: =SUMIFS('P&Ls Detailed'!W:W,'P&Ls Detailed'!$E:$E,'P&Ls Summary'!$D28,'P&Ls Detailed'!$D:$D,'P&Ls Summary'!$Y$3) -> 0 | J28: =SUMIFS('P&Ls Detailed'!X:X,'P&Ls Detailed'!$E:$E,'P&Ls Summary'!$D28,'P&Ls Detailed'!$D:$D,'P&Ls Summary'!$Y$3) -> 0 | K28: =SUMIFS('P&Ls Detailed'!Y:Y,'P&Ls Detailed'!$E:$E,'P&Ls Summary'!$D28,'P&Ls Detailed'!$D:$D,'P&Ls Summary'!$Y$3) -> 0 | L28: =SUMIFS('P&Ls Detailed'!Z:Z,'P&Ls Detailed'!$E:$E,'P&Ls Summary'!$D28,'P&Ls Detailed'!$D:$D,'P&Ls Summary'!$Y$3) -> 0 | M28: =SUMIFS('P&Ls Detailed'!AA:AA,'P&Ls Detailed'!$E:$E,'P&Ls Summary'!$D28,'P&Ls Detailed'!$D:$D,'P&Ls Summary'!$Y$3) -> 0 | O28: =P28/$AA$3 -> #DIV/0! | P28: =SUMIFS('P&Ls Detailed'!W:W,'P&Ls Detailed'!$E:$E,'P&Ls Summary'!$D28,'P&Ls Detailed'!$D:$D,'P&Ls Summary'!$Y$3)-SUMIFS('P&Ls Detailed'!W:W,'P&Ls Detailed'!$E:$E,'P&Ls Summary'!$D28,'P&Ls Detailed'!$D:$D,'P&Ls Summary'!$Y$3,'P&Ls Detailed'!$F:$F,"Exclude") -> 0 | R28: =AD28 -> #DIV/0! | S28: =R28*$AA$3 -> #DIV/0! | U28: =V28/$AA$3 -> #DIV/0! | V28: =S28*(1+$V$43) -> #DIV/0! | X28: =IF(AC28=1, IF(AND($AA$5=0,AC28=1),"T12","T12 + "&TEXT($AA$5,"0.0%")),TEXT(AB28,"$##,##0")&"/unit") -> T12 | AA28: =O28*(1+$AA$5) -> #DIV/0! | AB28: 0 | AC28: 1 | AD28: =CHOOSE(AC28,AA28,AB28) -> #DIV/0! | AE28: --> Use this line item if there is no breakdown of utilities in the T12/historical
D29: Utilities - Sewer & Water | H29: =I29/$AA$3 -> #DIV/0! | I29: =SUMIFS('P&Ls Detailed'!W:W,'P&Ls Detailed'!$E:$E,'P&Ls Summary'!$D29,'P&Ls Detailed'!$D:$D,'P&Ls Summary'!$Y$3) -> 220163.19 | J29: =SUMIFS('P&Ls Detailed'!X:X,'P&Ls Detailed'!$E:$E,'P&Ls Summary'!$D29,'P&Ls Detailed'!$D:$D,'P&Ls Summary'!$Y$3) -> 216784 | K29: =SUMIFS('P&Ls Detailed'!Y:Y,'P&Ls Detailed'!$E:$E,'P&Ls Summary'!$D29,'P&Ls Detailed'!$D:$D,'P&Ls Summary'!$Y$3) -> 212497.32 | L29: =SUMIFS('P&Ls Detailed'!Z:Z,'P&Ls Detailed'!$E:$E,'P&Ls Summary'!$D29,'P&Ls Detailed'!$D:$D,'P&Ls Summary'!$Y$3) -> 217894.72 | M29: =SUMIFS('P&Ls Detailed'!AA:AA,'P&Ls Detailed'!$E:$E,'P&Ls Summary'!$D29,'P&Ls Detailed'!$D:$D,'P&Ls Summary'!$Y$3) -> 217200 | O29: =P29/$AA$3 -> #DIV/0! | P29: =SUMIFS('P&Ls Detailed'!W:W,'P&Ls Detailed'!$E:$E,'P&Ls Summary'!$D29,'P&Ls Detailed'!$D:$D,'P&Ls Summary'!$Y$3)-SUMIFS('P&Ls Detailed'!W:W,'P&Ls Detailed'!$E:$E,'P&Ls Summary'!$D29,'P&Ls Detailed'!$D:$D,'P&Ls Summary'!$Y$3,'P&Ls Detailed'!$F:$F,"Exclude") -> 220163.19 | R29: =AD29 -> #DIV/0! | S29: =R29*$AA$3 -> #DIV/0! | U29: =V29/$AA$3 -> #DIV/0! | V29: =S29*(1+$V$43) -> #DIV/0! | X29: =IF(AC29=1, IF(AND($AA$5=0,AC29=1),"T12","T12 + "&TEXT($AA$5,"0.0%")),TEXT(AB29,"$##,##0")&"/unit") -> T12 | AA29: =O29*(1+$AA$5) -> #DIV/0! | AB29: 0 | AC29: 1 | AD29: =CHOOSE(AC29,AA29,AB29) -> #DIV/0!
D30: Utilities - Gas | H30: =I30/$AA$3 -> #DIV/0! | I30: =SUMIFS('P&Ls Detailed'!W:W,'P&Ls Detailed'!$E:$E,'P&Ls Summary'!$D30,'P&Ls Detailed'!$D:$D,'P&Ls Summary'!$Y$3) -> 282912.28 | J30: =SUMIFS('P&Ls Detailed'!X:X,'P&Ls Detailed'!$E:$E,'P&Ls Summary'!$D30,'P&Ls Detailed'!$D:$D,'P&Ls Summary'!$Y$3) -> 330328.85 | K30: =SUMIFS('P&Ls Detailed'!Y:Y,'P&Ls Detailed'!$E:$E,'P&Ls Summary'!$D30,'P&Ls Detailed'!$D:$D,'P&Ls Summary'!$Y$3) -> 415231.8 | L30: =SUMIFS('P&Ls Detailed'!Z:Z,'P&Ls Detailed'!$E:$E,'P&Ls Summary'!$D30,'P&Ls Detailed'!$D:$D,'P&Ls Summary'!$Y$3) -> 382871.8 | M30: =SUMIFS('P&Ls Detailed'!AA:AA,'P&Ls Detailed'!$E:$E,'P&Ls Summary'!$D30,'P&Ls Detailed'!$D:$D,'P&Ls Summary'!$Y$3) -> 309325.08 | O30: =P30/$AA$3 -> #DIV/0! | P30: =SUMIFS('P&Ls Detailed'!W:W,'P&Ls Detailed'!$E:$E,'P&Ls Summary'!$D30,'P&Ls Detailed'!$D:$D,'P&Ls Summary'!$Y$3)-SUMIFS('P&Ls Detailed'!W:W,'P&Ls Detailed'!$E:$E,'P&Ls Summary'!$D30,'P&Ls Detailed'!$D:$D,'P&Ls Summary'!$Y$3,'P&Ls Detailed'!$F:$F,"Exclude") -> 282912.28 | R30: =AD30 -> #DIV/0! | S30: =R30*$AA$3 -> #DIV/0! | U30: =V30/$AA$3 -> #DIV/0! | V30: =S30*(1+$V$43) -> #DIV/0! | X30: =IF(AC30=1, IF(AND($AA$5=0,AC30=1),"T12","T12 + "&TEXT($AA$5,"0.0%")),TEXT(AB30,"$##,##0")&"/unit") -> T12 | AA30: =O30*(1+$AA$5) -> #DIV/0! | AB30: 0 | AC30: 1 | AD30: =CHOOSE(AC30,AA30,AB30) -> #DIV/0!
D31: Utilities - Electric | H31: =I31/$AA$3 -> #DIV/0! | I31: =SUMIFS('P&Ls Detailed'!W:W,'P&Ls Detailed'!$E:$E,'P&Ls Summary'!$D31,'P&Ls Detailed'!$D:$D,'P&Ls Summary'!$Y$3) -> 83165.2 | J31: =SUMIFS('P&Ls Detailed'!X:X,'P&Ls Detailed'!$E:$E,'P&Ls Summary'!$D31,'P&Ls Detailed'!$D:$D,'P&Ls Summary'!$Y$3) -> 89129.067 | K31: =SUMIFS('P&Ls Detailed'!Y:Y,'P&Ls Detailed'!$E:$E,'P&Ls Summary'!$D31,'P&Ls Detailed'!$D:$D,'P&Ls Summary'!$Y$3) -> 92464.12 | L31: =SUMIFS('P&Ls Detailed'!Z:Z,'P&Ls Detailed'!$E:$E,'P&Ls Summary'!$D31,'P&Ls Detailed'!$D:$D,'P&Ls Summary'!$Y$3) -> 85245.64 | M31: =SUMIFS('P&Ls Detailed'!AA:AA,'P&Ls Detailed'!$E:$E,'P&Ls Summary'!$D31,'P&Ls Detailed'!$D:$D,'P&Ls Summary'!$Y$3) -> 88002.48 | O31: =P31/$AA$3 -> #DIV/0! | P31: =SUMIFS('P&Ls Detailed'!W:W,'P&Ls Detailed'!$E:$E,'P&Ls Summary'!$D31,'P&Ls Detailed'!$D:$D,'P&Ls Summary'!$Y$3)-SUMIFS('P&Ls Detailed'!W:W,'P&Ls Detailed'!$E:$E,'P&Ls Summary'!$D31,'P&Ls Detailed'!$D:$D,'P&Ls Summary'!$Y$3,'P&Ls Detailed'!$F:$F,"Exclude") -> 83165.2 | R31: =AD31 -> #DIV/0! | S31: =R31*$AA$3 -> #DIV/0! | U31: =V31/$AA$3 -> #DIV/0! | V31: =S31*(1+$V$43) -> #DIV/0! | X31: =IF(AC31=1, IF(AND($AA$5=0,AC31=1),"T12","T12 + "&TEXT($AA$5,"0.0%")),TEXT(AB31,"$##,##0")&"/unit") -> T12 | AA31: =O31*(1+$AA$5) -> #DIV/0! | AB31: 0 | AC31: 1 | AD31: =CHOOSE(AC31,AA31,AB31) -> #DIV/0!
D32: Repairs & Maintenance | H32: =I32/$AA$3 -> #DIV/0! | I32: =SUMIFS('P&Ls Detailed'!W:W,'P&Ls Detailed'!$E:$E,'P&Ls Summary'!$D32,'P&Ls Detailed'!$D:$D,'P&Ls Summary'!$Y$3) -> 508962.48 | J32: =SUMIFS('P&Ls Detailed'!X:X,'P&Ls Detailed'!$E:$E,'P&Ls Summary'!$D32,'P&Ls Detailed'!$D:$D,'P&Ls Summary'!$Y$3) -> 491326.83 | K32: =SUMIFS('P&Ls Detailed'!Y:Y,'P&Ls Detailed'!$E:$E,'P&Ls Summary'!$D32,'P&Ls Detailed'!$D:$D,'P&Ls Summary'!$Y$3) -> 447983.62 | L32: =SUMIFS('P&Ls Detailed'!Z:Z,'P&Ls Detailed'!$E:$E,'P&Ls Summary'!$D32,'P&Ls Detailed'!$D:$D,'P&Ls Summary'!$Y$3) -> 406646.92 | M32: =SUMIFS('P&Ls Detailed'!AA:AA,'P&Ls Detailed'!$E:$E,'P&Ls Summary'!$D32,'P&Ls Detailed'!$D:$D,'P&Ls Summary'!$Y$3) -> 454985.16 | O32: =P32/$AA$3 -> #DIV/0! | P32: =SUMIFS('P&Ls Detailed'!W:W,'P&Ls Detailed'!$E:$E,'P&Ls Summary'!$D32,'P&Ls Detailed'!$D:$D,'P&Ls Summary'!$Y$3)-SUMIFS('P&Ls Detailed'!W:W,'P&Ls Detailed'!$E:$E,'P&Ls Summary'!$D32,'P&Ls Detailed'!$D:$D,'P&Ls Summary'!$Y$3,'P&Ls Detailed'!$F:$F,"Exclude") -> 508962.48 | R32: =AD32 -> #DIV/0! | S32: =R32*$AA$3 -> #DIV/0! | U32: =V32/$AA$3 -> #DIV/0! | V32: =S32*(1+$V$43) -> #DIV/0! | X32: =IF(AC32=1, IF(AND($AA$5=0,AC32=1),"T12","T12 + "&TEXT($AA$5,"0.0%")),TEXT(AB32,"$##,##0")&"/unit") -> T12 | AA32: =O32*(1+$AA$5) -> #DIV/0! | AB32: 0 | AC32: 1 | AD32: =CHOOSE(AC32,AA32,AB32) -> #DIV/0!
D33: Contract Services | H33: =I33/$AA$3 -> #DIV/0! | I33: =SUMIFS('P&Ls Detailed'!W:W,'P&Ls Detailed'!$E:$E,'P&Ls Summary'!$D33,'P&Ls Detailed'!$D:$D,'P&Ls Summary'!$Y$3) -> 666619.11 | J33: =SUMIFS('P&Ls Detailed'!X:X,'P&Ls Detailed'!$E:$E,'P&Ls Summary'!$D33,'P&Ls Detailed'!$D:$D,'P&Ls Summary'!$Y$3) -> 650416.35 | K33: =SUMIFS('P&Ls Detailed'!Y:Y,'P&Ls Detailed'!$E:$E,'P&Ls Summary'!$D33,'P&Ls Detailed'!$D:$D,'P&Ls Summary'!$Y$3) -> 586004.46 | L33: =SUMIFS('P&Ls Detailed'!Z:Z,'P&Ls Detailed'!$E:$E,'P&Ls Summary'!$D33,'P&Ls Detailed'!$D:$D,'P&Ls Summary'!$Y$3) -> 571757.16 | M33: =SUMIFS('P&Ls Detailed'!AA:AA,'P&Ls Detailed'!$E:$E,'P&Ls Summary'!$D33,'P&Ls Detailed'!$D:$D,'P&Ls Summary'!$Y$3) -> 603813.72 | O33: =P33/$AA$3 -> #DIV/0! | P33: =SUMIFS('P&Ls Detailed'!W:W,'P&Ls Detailed'!$E:$E,'P&Ls Summary'!$D33,'P&Ls Detailed'!$D:$D,'P&Ls Summary'!$Y$3)-SUMIFS('P&Ls Detailed'!W:W,'P&Ls Detailed'!$E:$E,'P&Ls Summary'!$D33,'P&Ls Detailed'!$D:$D,'P&Ls Summary'!$Y$3,'P&Ls Detailed'!$F:$F,"Exclude") -> 666619.11 | R33: =AD33 -> #DIV/0! | S33: =R33*$AA$3 -> #DIV/0! | U33: =V33/$AA$3 -> #DIV/0! | V33: =S33*(1+$V$43) -> #DIV/0! | X33: =IF(AC33=1, IF(AND($AA$5=0,AC33=1),"T12","T12 + "&TEXT($AA$5,"0.0%")),TEXT(AB33,"$##,##0")&"/unit") -> T12 | AA33: =O33*(1+$AA$5) -> #DIV/0! | AB33: 0 | AC33: 1 | AD33: =CHOOSE(AC33,AA33,AB33) -> #DIV/0!
D34: General & Administrative | H34: =I34/$AA$3 -> #DIV/0! | I34: =SUMIFS('P&Ls Detailed'!W:W,'P&Ls Detailed'!$E:$E,'P&Ls Summary'!$D34,'P&Ls Detailed'!$D:$D,'P&Ls Summary'!$Y$3) -> 239070.86 | J34: =SUMIFS('P&Ls Detailed'!X:X,'P&Ls Detailed'!$E:$E,'P&Ls Summary'!$D34,'P&Ls Detailed'!$D:$D,'P&Ls Summary'!$Y$3) -> 234530.68 | K34: =SUMIFS('P&Ls Detailed'!Y:Y,'P&Ls Detailed'!$E:$E,'P&Ls Summary'!$D34,'P&Ls Detailed'!$D:$D,'P&Ls Summary'!$Y$3) -> 222801.2 | L34: =SUMIFS('P&Ls Detailed'!Z:Z,'P&Ls Detailed'!$E:$E,'P&Ls Summary'!$D34,'P&Ls Detailed'!$D:$D,'P&Ls Summary'!$Y$3) -> 206203.96 | M34: =SUMIFS('P&Ls Detailed'!AA:AA,'P&Ls Detailed'!$E:$E,'P&Ls Summary'!$D34,'P&Ls Detailed'!$D:$D,'P&Ls Summary'!$Y$3) -> 171118.68 | O34: =P34/$AA$3 -> #DIV/0! | P34: =SUMIFS('P&Ls Detailed'!W:W,'P&Ls Detailed'!$E:$E,'P&Ls Summary'!$D34,'P&Ls Detailed'!$D:$D,'P&Ls Summary'!$Y$3)-SUMIFS('P&Ls Detailed'!W:W,'P&Ls Detailed'!$E:$E,'P&Ls Summary'!$D34,'P&Ls Detailed'!$D:$D,'P&Ls Summary'!$Y$3,'P&Ls Detailed'!$F:$F,"Exclude") -> 239070.86 | R34: =AD34 -> #DIV/0! | S34: =R34*$AA$3 -> #DIV/0! | U34: =V34/$AA$3 -> #DIV/0! | V34: =S34*(1+$V$43) -> #DIV/0! | X34: =IF(AC34=1, IF(AND($AA$5=0,AC34=1),"T12","T12 + "&TEXT($AA$5,"0.0%")),TEXT(AB34,"$##,##0")&"/unit") -> T12 | AA34: =O34*(1+$AA$5) -> #DIV/0! | AB34: 0 | AC34: 1 | AD34: =CHOOSE(AC34,AA34,AB34) -> #DIV/0!
D35: Advertising & Marketing | H35: =I35/$AA$3 -> #DIV/0! | I35: =SUMIFS('P&Ls Detailed'!W:W,'P&Ls Detailed'!$E:$E,'P&Ls Summary'!$D35,'P&Ls Detailed'!$D:$D,'P&Ls Summary'!$Y$3) -> 16948.87 | J35: =SUMIFS('P&Ls Detailed'!X:X,'P&Ls Detailed'!$E:$E,'P&Ls Summary'!$D35,'P&Ls Detailed'!$D:$D,'P&Ls Summary'!$Y$3) -> 15091.827 | K35: =SUMIFS('P&Ls Detailed'!Y:Y,'P&Ls Detailed'!$E:$E,'P&Ls Summary'!$D35,'P&Ls Detailed'!$D:$D,'P&Ls Summary'!$Y$3) -> 16140 | L35: =SUMIFS('P&Ls Detailed'!Z:Z,'P&Ls Detailed'!$E:$E,'P&Ls Summary'!$D35,'P&Ls Detailed'!$D:$D,'P&Ls Summary'!$Y$3) -> 13700 | M35: =SUMIFS('P&Ls Detailed'!AA:AA,'P&Ls Detailed'!$E:$E,'P&Ls Summary'!$D35,'P&Ls Detailed'!$D:$D,'P&Ls Summary'!$Y$3) -> 10500 | O35: =P35/$AA$3 -> #DIV/0! | P35: =SUMIFS('P&Ls Detailed'!W:W,'P&Ls Detailed'!$E:$E,'P&Ls Summary'!$D35,'P&Ls Detailed'!$D:$D,'P&Ls Summary'!$Y$3)-SUMIFS('P&Ls Detailed'!W:W,'P&Ls Detailed'!$E:$E,'P&Ls Summary'!$D35,'P&Ls Detailed'!$D:$D,'P&Ls Summary'!$Y$3,'P&Ls Detailed'!$F:$F,"Exclude") -> 16948.87 | R35: =AD35 -> #DIV/0! | S35: =R35*$AA$3 -> #DIV/0! | U35: =V35/$AA$3 -> #DIV/0! | V35: =S35*(1+$V$43) -> #DIV/0! | X35: =IF(AC35=1, IF(AND($AA$5=0,AC35=1),"T12","T12 + "&TEXT($AA$5,"0.0%")),TEXT(AB35,"$##,##0")&"/unit") -> T12 | AA35: =O35*(1+$AA$5) -> #DIV/0! | AB35: 0 | AC35: 1 | AD35: =CHOOSE(AC35,AA35,AB35) -> #DIV/0!
D36: Personnel | H36: =I36/$AA$3 -> #DIV/0! | I36: =SUMIFS('P&Ls Detailed'!W:W,'P&Ls Detailed'!$E:$E,'P&Ls Summary'!$D36,'P&Ls Detailed'!$D:$D,'P&Ls Summary'!$Y$3) -> 1381090.5 | J36: =SUMIFS('P&Ls Detailed'!X:X,'P&Ls Detailed'!$E:$E,'P&Ls Summary'!$D36,'P&Ls Detailed'!$D:$D,'P&Ls Summary'!$Y$3) -> 1410938.2 | K36: =SUMIFS('P&Ls Detailed'!Y:Y,'P&Ls Detailed'!$E:$E,'P&Ls Summary'!$D36,'P&Ls Detailed'!$D:$D,'P&Ls Summary'!$Y$3) -> 1423219.7 | L36: =SUMIFS('P&Ls Detailed'!Z:Z,'P&Ls Detailed'!$E:$E,'P&Ls Summary'!$D36,'P&Ls Detailed'!$D:$D,'P&Ls Summary'!$Y$3) -> 1289361.5 | M36: =SUMIFS('P&Ls Detailed'!AA:AA,'P&Ls Detailed'!$E:$E,'P&Ls Summary'!$D36,'P&Ls Detailed'!$D:$D,'P&Ls Summary'!$Y$3) -> 1253655.5 | O36: =P36/$AA$3 -> #DIV/0! | P36: =SUMIFS('P&Ls Detailed'!W:W,'P&Ls Detailed'!$E:$E,'P&Ls Summary'!$D36,'P&Ls Detailed'!$D:$D,'P&Ls Summary'!$Y$3)-SUMIFS('P&Ls Detailed'!W:W,'P&Ls Detailed'!$E:$E,'P&Ls Summary'!$D36,'P&Ls Detailed'!$D:$D,'P&Ls Summary'!$Y$3,'P&Ls Detailed'!$F:$F,"Exclude") -> 512779.6 | R36: =AD36 -> #DIV/0! | S36: =R36*$AA$3 -> #DIV/0! | U36: =V36/$AA$3 -> #DIV/0! | V36: =S36*(1+$V$43) -> #DIV/0! | X36: =IF(AC36=1, IF(AND($AA$5=0,AC36=1),"T12","T12 + "&TEXT($AA$5,"0.0%")),TEXT(AB36,"$##,##0")&"/unit") -> T12 | AA36: =O36*(1+$AA$5) -> #DIV/0! | AB36: 0 | AC36: 1 | AD36: =CHOOSE(AC36,AA36,AB36) -> #DIV/0!
D37: Management Fee | H37: =I37/$AA$3 -> #DIV/0! | I37: =SUMIFS('P&Ls Detailed'!W:W,'P&Ls Detailed'!$E:$E,'P&Ls Summary'!$D37,'P&Ls Detailed'!$D:$D,'P&Ls Summary'!$Y$3) -> 530572 | J37: =SUMIFS('P&Ls Detailed'!X:X,'P&Ls Detailed'!$E:$E,'P&Ls Summary'!$D37,'P&Ls Detailed'!$D:$D,'P&Ls Summary'!$Y$3) -> 537656 | K37: =SUMIFS('P&Ls Detailed'!Y:Y,'P&Ls Detailed'!$E:$E,'P&Ls Summary'!$D37,'P&Ls Detailed'!$D:$D,'P&Ls Summary'!$Y$3) -> 545684 | L37: =SUMIFS('P&Ls Detailed'!Z:Z,'P&Ls Detailed'!$E:$E,'P&Ls Summary'!$D37,'P&Ls Detailed'!$D:$D,'P&Ls Summary'!$Y$3) -> 540784 | M37: =SUMIFS('P&Ls Detailed'!AA:AA,'P&Ls Detailed'!$E:$E,'P&Ls Summary'!$D37,'P&Ls Detailed'!$D:$D,'P&Ls Summary'!$Y$3) -> 542424 | O37: =P37/$AA$3 -> #DIV/0! | P37: =SUMIFS('P&Ls Detailed'!W:W,'P&Ls Detailed'!$E:$E,'P&Ls Summary'!$D37,'P&Ls Detailed'!$D:$D,'P&Ls Summary'!$Y$3)-SUMIFS('P&Ls Detailed'!W:W,'P&Ls Detailed'!$E:$E,'P&Ls Summary'!$D37,'P&Ls Detailed'!$D:$D,'P&Ls Summary'!$Y$3,'P&Ls Detailed'!$F:$F,"Exclude") -> 530572 | R37: =S37/$AA$3 -> #DIV/0! | S37: =$AC$37*S23 -> #DIV/0! | U37: =V37/$AA$3 -> #DIV/0! | V37: =$AC$37*V23 -> #DIV/0! | X37: =TEXT(AC37,"##.0%")&" of EGI" -> 3.0% of EGI | AA37: =O37*(1+$AA$5) -> #DIV/0! | AB37: =S37/'P&Ls Summary'!$AA$3 -> #DIV/0! | AC37: 0.03 | AD37: =-AB37 -> #DIV/0! | AE37: --> Default to 3.0%
D38: Replacement Reserves | H38: =I38/$AA$3 -> #DIV/0! | I38: =SUMIFS('P&Ls Detailed'!W:W,'P&Ls Detailed'!$E:$E,'P&Ls Summary'!$D38,'P&Ls Detailed'!$D:$D,'P&Ls Summary'!$Y$3) -> 0 | J38: =SUMIFS('P&Ls Detailed'!X:X,'P&Ls Detailed'!$E:$E,'P&Ls Summary'!$D38,'P&Ls Detailed'!$D:$D,'P&Ls Summary'!$Y$3) -> 0 | K38: =SUMIFS('P&Ls Detailed'!Y:Y,'P&Ls Detailed'!$E:$E,'P&Ls Summary'!$D38,'P&Ls Detailed'!$D:$D,'P&Ls Summary'!$Y$3) -> 0 | L38: =SUMIFS('P&Ls Detailed'!Z:Z,'P&Ls Detailed'!$E:$E,'P&Ls Summary'!$D38,'P&Ls Detailed'!$D:$D,'P&Ls Summary'!$Y$3) -> 0 | M38: =SUMIFS('P&Ls Detailed'!AA:AA,'P&Ls Detailed'!$E:$E,'P&Ls Summary'!$D38,'P&Ls Detailed'!$D:$D,'P&Ls Summary'!$Y$3) -> 0 | O38: =P38/$AA$3 -> #DIV/0! | P38: =SUMIFS('P&Ls Detailed'!W:W,'P&Ls Detailed'!$E:$E,'P&Ls Summary'!$D38,'P&Ls Detailed'!$D:$D,'P&Ls Summary'!$Y$3)-SUMIFS('P&Ls Detailed'!W:W,'P&Ls Detailed'!$E:$E,'P&Ls Summary'!$D38,'P&Ls Detailed'!$D:$D,'P&Ls Summary'!$Y$3,'P&Ls Detailed'!$F:$F,"Exclude") -> 0 | R38: =AD38 -> #DIV/0! | S38: =R38*$AA$3 -> #DIV/0! | U38: =V38/$AA$3 -> #DIV/0! | V38: =S38*(1+$V$43) -> #DIV/0! | X38: =IF(AC38=1, IF(AND($AA$5=0,AC38=1),"T12","T12 + "&TEXT($AA$5,"0.0%")),TEXT(AB38,"$##,##0")&"/unit") -> T12 | AA38: =O38*(1+$AA$5) -> #DIV/0! | AB38: 250 | AC38: 1 | AD38: =CHOOSE(AC38,AA38,AB38) -> #DIV/0! | AE38: --> Default to $0
D39: Total Operating Expenses | E39: =SUM(E26:E38) -> 0 | F39: =SUM(F26:F38) -> 0 | G39: =SUM(G26:G38) -> 0 | H39: =I39/$AA$3 -> #DIV/0! | I39: =SUM(I26:I38) -> 5517778.2 | J39: =SUM(J26:J38) -> 5582548 | K39: =SUM(K26:K38) -> 5583760.2 | L39: =SUM(L26:L38) -> 5353873.6 | M39: =SUM(M26:M38) -> 5290432.4 | O39: =P39/$AA$3 -> #DIV/0! | P39: =SUM(P26:P38) -> 4649467.3 | R39: =S39/$AA$3 -> #DIV/0! | S39: =SUM(S26:S38) -> #DIV/0! | U39: =V39/$AA$3 -> #DIV/0! | V39: =SUM(V26:V38) -> #DIV/0!
D40: Net Operating Income | E40: =E23-E39 -> 0 | F40: =F23-F39 -> 0 | G40: =G23-G39 -> 0 | H40: =I40/$AA$3 -> #DIV/0! | I40: =I23-I39 -> 6299663.2 | J40: =J23-J39 -> 6347669.3 | K40: =K23-K39 -> 6447476 | L40: =L23-L39 -> 6788027.7 | M40: =M23-M39 -> 6902808.5 | O40: =P40/$AA$3 -> #DIV/0! | P40: =P23-P39 -> -4043660.3 | R40: =S40/$AA$3 -> #DIV/0! | S40: =S23-S39 -> #DIV/0! | U40: =V40/$AA$3 -> #DIV/0! | V40: =V23-V39 -> #DIV/0!
O42: In-Place Notes: | R42: Rent Inc > IP --> | S42: 0 | U42: Rent Inc > IP--> | V42: 0
O43: - In-Place rental revenue from RR | R43: IP Notes: | U43: Oth Inc / OpEx Inc > IP--> | V43: 0
O44: - OpEx is T12 Minus Exclusions on 'P&L Detailed' Tab | R44: - In-Place rental revenue from RR plus market rates for vacant units, plus growth factor above | U44: Stabilized Notes:
...

Sheet 10-Yr CF
B3: 0 | C3: 10-YEAR CASH FLOW | O3: ='Exec Summ'!$F$6 -> Hudson View Park
E5: 1 | F5: =E5+1 -> 2 | G5: =F5+1 -> 3 | H5: =G5+1 -> 4 | I5: =H5+1 -> 5 | J5: =I5+1 -> 6 | K5: =J5+1 -> 7 | L5: =K5+1 -> 8 | M5: =L5+1 -> 9 | N5: =M5+1 -> 10 | Q5: % Growth / Assumption
D7: Income
D8: Market Rent | E8: =INDEX('P&Ls Summary'!$S$9:$S$40,MATCH('10-Yr CF'!D8,'P&Ls Summary'!$D$9:$D$40,0)) -> #DIV/0! | F8: =E8*(1+$Q8) -> #DIV/0! | G8: =F8*(1+$Q8) -> #DIV/0! | H8: =G8*(1+$Q8) -> #DIV/0! | I8: =H8*(1+$Q8) -> #DIV/0! | J8: =I8*(1+$Q8) -> #DIV/0! | K8: =J8*(1+$Q8) -> #DIV/0! | L8: =K8*(1+$Q8) -> #DIV/0! | M8: =L8*(1+$Q8) -> #DIV/0! | N8: =M8*(1+$Q8) -> #DIV/0! | Q8: 0.03 | T8: Yrs to Stabilize
D9: Loss to Lease | E9: =INDEX('P&Ls Summary'!$S$9:$S$40,MATCH('10-Yr CF'!D9,'P&Ls Summary'!$D$9:$D$40,0)) -> #DIV/0! | F9: =IF(F5>$T$9,-F8*$Q$9,(1-(E5/$T$9))*$E$9) -> #DIV/0! | G9: =IF(G5>$T$9,-G8*$Q$9,(1-(F5/$T$9))*$E$9) -> #DIV/0! | H9: =IF(H5>$T$9,-H8*$Q$9,(1-(G5/$T$9))*$E$9) -> #DIV/0! | I9: =IF(I5>$T$9,-I8*$Q$9,(1-(H5/$T$9))*$E$9) -> #DIV/0! | J9: =IF(J5>$T$9,-J8*$Q$9,(1-(I5/$T$9))*$E$9) -> #DIV/0! | K9: =IF(K5>$T$9,-K8*$Q$9,(1-(J5/$T$9))*$E$9) -> #DIV/0! | L9: =IF(L5>$T$9,-L8*$Q$9,(1-(K5/$T$9))*$E$9) -> #DIV/0! | M9: =IF(M5>$T$9,-M8*$Q$9,(1-(L5/$T$9))*$E$9) -> #DIV/0! | N9: =IF(N5>$T$9,-N8*$Q$9,(1-(M5/$T$9))*$E$9) -> #DIV/0! | Q9: 0.015 | R9: Stabilized % | T9: 4 | U9: ="--> after Y"&T9&", LTL will be based on "&TEXT(Q9,"0.0%")&" of Market Rent" -> --> after Y4, LTL will be based on 1.5% of Market Rent
D10: Gross Rental Income | E10: =SUM(E8:E9) -> #DIV/0! | F10: =SUM(F8:F9) -> #DIV/0! | G10: =SUM(G8:G9) -> #DIV/0! | H10: =SUM(H8:H9) -> #DIV/0! | I10: =SUM(I8:I9) -> #DIV/0! | J10: =SUM(J8:J9) -> #DIV/0! | K10: =SUM(K8:K9) -> #DIV/0! | L10: =SUM(L8:L9) -> #DIV/0! | ... N10: =SUM(N8:N9) -> #DIV/0!
D11: Less Vacancy | E11: =INDEX('P&Ls Summary'!$S$9:$S$40,MATCH('10-Yr CF'!D11,'P&Ls Summary'!$D$9:$D$40,0)) -> 0 | F11: =-$Q11*F$10 -> #DIV/0! | G11: =-$Q11*G$10 -> #DIV/0! | H11: =-$Q11*H$10 -> #DIV/0! | I11: =-$Q11*I$10 -> #DIV/0! | J11: =-$Q11*J$10 -> #DIV/0! | K11: =-$Q11*K$10 -> #DIV/0! | L11: =-$Q11*L$10 -> #DIV/0! | M11: =-$Q11*M$10 -> #DIV/0! | N11: =-$Q11*N$10 -> #DIV/0! | Q11: ='P&Ls Summary'!AC12 -> 0.03 | R11: of Gross Rental Income
D12: Less: Concessions | E12: =INDEX('P&Ls Summary'!$S$9:$S$40,MATCH('10-Yr CF'!D12,'P&Ls Summary'!$D$9:$D$40,0)) -> 0 | F12: =-$Q12*F$10 -> #DIV/0! | G12: =-$Q12*G$10 -> #DIV/0! | H12: =-$Q12*H$10 -> #DIV/0! | I12: =-$Q12*I$10 -> #DIV/0! | J12: =-$Q12*J$10 -> #DIV/0! | K12: =-$Q12*K$10 -> #DIV/0! | L12: =-$Q12*L$10 -> #DIV/0! | M12: =-$Q12*M$10 -> #DIV/0! | N12: =-$Q12*N$10 -> #DIV/0! | Q12: ='P&Ls Summary'!AC13 -> 0 | R12: of Gross Rental Income
D13: Less: Bad Debt/Collection | E13: =INDEX('P&Ls Summary'!$S$9:$S$40,MATCH('10-Yr CF'!D13,'P&Ls Summary'!$D$9:$D$40,0)) -> 0 | F13: =-$Q13*F$10 -> #DIV/0! | G13: =-$Q13*G$10 -> #DIV/0! | H13: =-$Q13*H$10 -> #DIV/0! | I13: =-$Q13*I$10 -> #DIV/0! | J13: =-$Q13*J$10 -> #DIV/0! | K13: =-$Q13*K$10 -> #DIV/0! | L13: =-$Q13*L$10 -> #DIV/0! | M13: =-$Q13*M$10 -> #DIV/0! | N13: =-$Q13*N$10 -> #DIV/0! | Q13: ='P&Ls Summary'!AC14 -> 0 | R13: of Gross Rental Income
D14: Pet Income | E14: =INDEX('P&Ls Summary'!$S$9:$S$40,MATCH('10-Yr CF'!D14,'P&Ls Summary'!$D$9:$D$40,0)) -> #DIV/0! | F14: =E14*(1+$Q14) -> #DIV/0! | G14: =F14*(1+$Q14) -> #DIV/0! | H14: =G14*(1+$Q14) -> #DIV/0! | I14: =H14*(1+$Q14) -> #DIV/0! | J14: =I14*(1+$Q14) -> #DIV/0! | K14: =J14*(1+$Q14) -> #DIV/0! | L14: =K14*(1+$Q14) -> #DIV/0! | M14: =L14*(1+$Q14) -> #DIV/0! | N14: =M14*(1+$Q14) -> #DIV/0! | Q14: 0.025
D15: Laundry Income | E15: =INDEX('P&Ls Summary'!$S$9:$S$40,MATCH('10-Yr CF'!D15,'P&Ls Summary'!$D$9:$D$40,0)) -> #DIV/0! | F15: =E15*(1+$Q15) -> #DIV/0! | G15: =F15*(1+$Q15) -> #DIV/0! | H15: =G15*(1+$Q15) -> #DIV/0! | I15: =H15*(1+$Q15) -> #DIV/0! | J15: =I15*(1+$Q15) -> #DIV/0! | K15: =J15*(1+$Q15) -> #DIV/0! | L15: =K15*(1+$Q15) -> #DIV/0! | M15: =L15*(1+$Q15) -> #DIV/0! | N15: =M15*(1+$Q15) -> #DIV/0! | Q15: =$Q$14 -> 0.025
D16: Parking Income | E16: =INDEX('P&Ls Summary'!$S$9:$S$40,MATCH('10-Yr CF'!D16,'P&Ls Summary'!$D$9:$D$40,0)) -> #DIV/0! | F16: =E16*(1+$Q16) -> #DIV/0! | G16: =F16*(1+$Q16) -> #DIV/0! | H16: =G16*(1+$Q16) -> #DIV/0! | I16: =H16*(1+$Q16) -> #DIV/0! | J16: =I16*(1+$Q16) -> #DIV/0! | K16: =J16*(1+$Q16) -> #DIV/0! | L16: =K16*(1+$Q16) -> #DIV/0! | M16: =L16*(1+$Q16) -> #DIV/0! | N16: =M16*(1+$Q16) -> #DIV/0! | Q16: =$Q$14 -> 0.025
D17: Storage Income | E17: =INDEX('P&Ls Summary'!$S$9:$S$40,MATCH('10-Yr CF'!D17,'P&Ls Summary'!$D$9:$D$40,0)) -> #DIV/0! | F17: =E17*(1+$Q17) -> #DIV/0! | G17: =F17*(1+$Q17) -> #DIV/0! | H17: =G17*(1+$Q17) -> #DIV/0! | I17: =H17*(1+$Q17) -> #DIV/0! | J17: =I17*(1+$Q17) -> #DIV/0! | K17: =J17*(1+$Q17) -> #DIV/0! | L17: =K17*(1+$Q17) -> #DIV/0! | M17: =L17*(1+$Q17) -> #DIV/0! | N17: =M17*(1+$Q17) -> #DIV/0! | Q17: =$Q$14 -> 0.025
D18: Utility Reimbursement | E18: =INDEX('P&Ls Summary'!$S$9:$S$40,MATCH('10-Yr CF'!D18,'P&Ls Summary'!$D$9:$D$40,0)) -> #DIV/0! | F18: =E18*(1+$Q18) -> #DIV/0! | G18: =F18*(1+$Q18) -> #DIV/0! | H18: =G18*(1+$Q18) -> #DIV/0! | I18: =H18*(1+$Q18) -> #DIV/0! | J18: =I18*(1+$Q18) -> #DIV/0! | K18: =J18*(1+$Q18) -> #DIV/0! | L18: =K18*(1+$Q18) -> #DIV/0! | M18: =L18*(1+$Q18) -> #DIV/0! | N18: =M18*(1+$Q18) -> #DIV/0! | Q18: =$Q$14 -> 0.025
D19: Other Income | E19: =INDEX('P&Ls Summary'!$S$9:$S$40,MATCH('10-Yr CF'!D19,'P&Ls Summary'!$D$9:$D$40,0)) -> #DIV/0! | F19: =E19*(1+$Q19) -> #DIV/0! | G19: =F19*(1+$Q19) -> #DIV/0! | H19: =G19*(1+$Q19) -> #DIV/0! | I19: =H19*(1+$Q19) -> #DIV/0! | J19: =I19*(1+$Q19) -> #DIV/0! | K19: =J19*(1+$Q19) -> #DIV/0! | L19: =K19*(1+$Q19) -> #DIV/0! | M19: =L19*(1+$Q19) -> #DIV/0! | N19: =M19*(1+$Q19) -> #DIV/0! | Q19: =$Q$14 -> 0.025
D20: Commercial Income | E20: =INDEX('P&Ls Summary'!$S$9:$S$40,MATCH('10-Yr CF'!D20,'P&Ls Summary'!$D$9:$D$40,0)) -> 0 | F20: =E20*(1+$Q20) -> 0 | G20: =F20*(1+$Q20) -> 0 | H20: =G20*(1+$Q20) -> 0 | I20: =H20*(1+$Q20) -> 0 | J20: =I20*(1+$Q20) -> 0 | K20: =J20*(1+$Q20) -> 0 | L20: =K20*(1+$Q20) -> 0 | M20: =L20*(1+$Q20) -> 0 | N20: =M20*(1+$Q20) -> 0 | Q20: =$Q$14 -> 0.025
D21: Less Commercial Vacancy | E21: =INDEX('P&Ls Summary'!$S$9:$S$40,MATCH('10-Yr CF'!D21,'P&Ls Summary'!$D$9:$D$40,0)) -> 0 | F21: =-$Q21*F$20 -> 0 | G21: =-$Q21*G$20 -> 0 | H21: =-$Q21*H$20 -> 0 | I21: =-$Q21*I$20 -> 0 | J21: =-$Q21*J$20 -> 0 | K21: =-$Q21*K$20 -> 0 | L21: =-$Q21*L$20 -> 0 | M21: =-$Q21*M$20 -> 0 | N21: =-$Q21*N$20 -> 0 | Q21: ='P&Ls Summary'!AC22 -> 0.05 | R21: of Commercial Income
D22: Effective Gross Income | E22: =SUM(E10:E21) -> #DIV/0! | F22: =SUM(F10:F21) -> #DIV/0! | G22: =SUM(G10:G21) -> #DIV/0! | H22: =SUM(H10:H21) -> #DIV/0! | I22: =SUM(I10:I21) -> #DIV/0! | J22: =SUM(J10:J21) -> #DIV/0! | K22: =SUM(K10:K21) -> #DIV/0! | L22: =SUM(L10:L21) -> #DIV/0! | ... N22: =SUM(N10:N21) -> #DIV/0!
D24: Expenses
D25: Property Taxes | E25: =INDEX('P&Ls Summary'!$S$9:$S$40,MATCH('10-Yr CF'!D25,'P&Ls Summary'!$D$9:$D$40,0)) -> #DIV/0! | F25: =E25*(1+$Q25) -> #DIV/0! | G25: =F25*(1+$Q25) -> #DIV/0! | H25: =G25*(1+$Q25) -> #DIV/0! | I25: =H25*(1+$Q25) -> #DIV/0! | J25: =I25*(1+$Q25) -> #DIV/0! | K25: =J25*(1+$Q25) -> #DIV/0! | L25: =K25*(1+$Q25) -> #DIV/0! | M25: =L25*(1+$Q25) -> #DIV/0! | N25: =M25*(1+$Q25) -> #DIV/0! | Q25: =$Q$14 -> 0.025
D26: Insurance | E26: =INDEX('P&Ls Summary'!$S$9:$S$40,MATCH('10-Yr CF'!D26,'P&Ls Summary'!$D$9:$D$40,0)) -> #DIV/0! | F26: =E26*(1+$Q26) -> #DIV/0! | G26: =F26*(1+$Q26) -> #DIV/0! | H26: =G26*(1+$Q26) -> #DIV/0! | I26: =H26*(1+$Q26) -> #DIV/0! | J26: =I26*(1+$Q26) -> #DIV/0! | K26: =J26*(1+$Q26) -> #DIV/0! | L26: =K26*(1+$Q26) -> #DIV/0! | M26: =L26*(1+$Q26) -> #DIV/0! | N26: =M26*(1+$Q26) -> #DIV/0! | Q26: =$Q$14 -> 0.025
D27: Utilities | E27: =INDEX('P&Ls Summary'!$S$9:$S$40,MATCH('10-Yr CF'!D27,'P&Ls Summary'!$D$9:$D$40,0)) -> #DIV/0! | F27: =E27*(1+$Q27) -> #DIV/0! | G27: =F27*(1+$Q27) -> #DIV/0! | H27: =G27*(1+$Q27) -> #DIV/0! | I27: =H27*(1+$Q27) -> #DIV/0! | J27: =I27*(1+$Q27) -> #DIV/0! | K27: =J27*(1+$Q27) -> #DIV/0! | L27: =K27*(1+$Q27) -> #DIV/0! | M27: =L27*(1+$Q27) -> #DIV/0! | N27: =M27*(1+$Q27) -> #DIV/0! | Q27: =$Q$14 -> 0.025
D28: Utilities - Sewer & Water | E28: =INDEX('P&Ls Summary'!$S$9:$S$40,MATCH('10-Yr CF'!D28,'P&Ls Summary'!$D$9:$D$40,0)) -> #DIV/0! | F28: =E28*(1+$Q28) -> #DIV/0! | G28: =F28*(1+$Q28) -> #DIV/0! | H28: =G28*(1+$Q28) -> #DIV/0! | I28: =H28*(1+$Q28) -> #DIV/0! | J28: =I28*(1+$Q28) -> #DIV/0! | K28: =J28*(1+$Q28) -> #DIV/0! | L28: =K28*(1+$Q28) -> #DIV/0! | M28: =L28*(1+$Q28) -> #DIV/0! | N28: =M28*(1+$Q28) -> #DIV/0! | Q28: =$Q$14 -> 0.025
D29: Utilities - Gas | E29: =INDEX('P&Ls Summary'!$S$9:$S$40,MATCH('10-Yr CF'!D29,'P&Ls Summary'!$D$9:$D$40,0)) -> #DIV/0! | F29: =E29*(1+$Q29) -> #DIV/0! | G29: =F29*(1+$Q29) -> #DIV/0! | H29: =G29*(1+$Q29) -> #DIV/0! | I29: =H29*(1+$Q29) -> #DIV/0! | J29: =I29*(1+$Q29) -> #DIV/0! | K29: =J29*(1+$Q29) -> #DIV/0! | L29: =K29*(1+$Q29) -> #DIV/0! | M29: =L29*(1+$Q29) -> #DIV/0! | N29: =M29*(1+$Q29) -> #DIV/0! | Q29: =$Q$14 -> 0.025
D30: Utilities - Electric | E30: =INDEX('P&Ls Summary'!$S$9:$S$40,MATCH('10-Yr CF'!D30,'P&Ls Summary'!$D$9:$D$40,0)) -> #DIV/0! | F30: =E30*(1+$Q30) -> #DIV/0! | G30: =F30*(1+$Q30) -> #DIV/0! | H30: =G30*(1+$Q30) -> #DIV/0! | I30: =H30*(1+$Q30) -> #DIV/0! | J30: =I30*(1+$Q30) -> #DIV/0! | K30: =J30*(1+$Q30) -> #DIV/0! | L30: =K30*(1+$Q30) -> #DIV/0! | M30: =L30*(1+$Q30) -> #DIV/0! | N30: =M30*(1+$Q30) -> #DIV/0! | Q30: =$Q$14 -> 0.025
D31: Repairs & Maintenance | E31: =INDEX('P&Ls Summary'!$S$9:$S$40,MATCH('10-Yr CF'!D31,'P&Ls Summary'!$D$9:$D$40,0)) -> #DIV/0! | F31: =E31*(1+$Q31) -> #DIV/0! | G31: =F31*(1+$Q31) -> #DIV/0! | H31: =G31*(1+$Q31) -> #DIV/0! | I31: =H31*(1+$Q31) -> #DIV/0! | J31: =I31*(1+$Q31) -> #DIV/0! | K31: =J31*(1+$Q31) -> #DIV/0! | L31: =K31*(1+$Q31) -> #DIV/0! | M31: =L31*(1+$Q31) -> #DIV/0! | N31: =M31*(1+$Q31) -> #DIV/0! | Q31: =$Q$14 -> 0.025
D32: Contract Services | E32: =INDEX('P&Ls Summary'!$S$9:$S$40,MATCH('10-Yr CF'!D32,'P&Ls Summary'!$D$9:$D$40,0)) -> #DIV/0! | F32: =E32*(1+$Q32) -> #DIV/0! | G32: =F32*(1+$Q32) -> #DIV/0! | H32: =G32*(1+$Q32) -> #DIV/0! | I32: =H32*(1+$Q32) -> #DIV/0! | J32: =I32*(1+$Q32) -> #DIV/0! | K32: =J32*(1+$Q32) -> #DIV/0! | L32: =K32*(1+$Q32) -> #DIV/0! | M32: =L32*(1+$Q32) -> #DIV/0! | N32: =M32*(1+$Q32) -> #DIV/0! | Q32: =$Q$14 -> 0.025
D33: General & Administrative | E33: =INDEX('P&Ls Summary'!$S$9:$S$40,MATCH('10-Yr CF'!D33,'P&Ls Summary'!$D$9:$D$40,0)) -> #DIV/0! | F33: =E33*(1+$Q33) -> #DIV/0! | G33: =F33*(1+$Q33) -> #DIV/0! | H33: =G33*(1+$Q33) -> #DIV/0! | I33: =H33*(1+$Q33) -> #DIV/0! | J33: =I33*(1+$Q33) -> #DIV/0! | K33: =J33*(1+$Q33) -> #DIV/0! | L33: =K33*(1+$Q33) -> #DIV/0! | M33: =L33*(1+$Q33) -> #DIV/0! | N33: =M33*(1+$Q33) -> #DIV/0! | Q33: =$Q$14 -> 0.025
D34: Advertising & Marketing | E34: =INDEX('P&Ls Summary'!$S$9:$S$40,MATCH('10-Yr CF'!D34,'P&Ls Summary'!$D$9:$D$40,0)) -> #DIV/0! | F34: =E34*(1+$Q34) -> #DIV/0! | G34: =F34*(1+$Q34) -> #DIV/0! | H34: =G34*(1+$Q34) -> #DIV/0! | I34: =H34*(1+$Q34) -> #DIV/0! | J34: =I34*(1+$Q34) -> #DIV/0! | K34: =J34*(1+$Q34) -> #DIV/0! | L34: =K34*(1+$Q34) -> #DIV/0! | M34: =L34*(1+$Q34) -> #DIV/0! | N34: =M34*(1+$Q34) -> #DIV/0! | Q34: =$Q$14 -> 0.025
D35: Personnel | E35: =INDEX('P&Ls Summary'!$S$9:$S$40,MATCH('10-Yr CF'!D35,'P&Ls Summary'!$D$9:$D$40,0)) -> #DIV/0! | F35: =E35*(1+$Q35) -> #DIV/0! | G35: =F35*(1+$Q35) -> #DIV/0! | H35: =G35*(1+$Q35) -> #DIV/0! | I35: =H35*(1+$Q35) -> #DIV/0! | J35: =I35*(1+$Q35) -> #DIV/0! | K35: =J35*(1+$Q35) -> #DIV/0! | L35: =K35*(1+$Q35) -> #DIV/0! | M35: =L35*(1+$Q35) -> #DIV/0! | N35: =M35*(1+$Q35) -> #DIV/0! | Q35: =$Q$14 -> 0.025
D36: Management Fee | E36: =INDEX('P&Ls Summary'!$S$9:$S$40,MATCH('10-Yr CF'!D36,'P&Ls Summary'!$D$9:$D$40,0)) -> #DIV/0! | F36: =$Q$36*F22 -> #DIV/0! | G36: =$Q$36*G22 -> #DIV/0! | H36: =$Q$36*H22 -> #DIV/0! | I36: =$Q$36*I22 -> #DIV/0! | J36: =$Q$36*J22 -> #DIV/0! | K36: =$Q$36*K22 -> #DIV/0! | L36: =$Q$36*L22 -> #DIV/0! | M36: =$Q$36*M22 -> #DIV/0! | N36: =$Q$36*N22 -> #DIV/0! | Q36: ='P&Ls Summary'!AC37 -> 0.03 | R36: of EGI
D37: Replacement Reserves | E37: =INDEX('P&Ls Summary'!$S$9:$S$40,MATCH('10-Yr CF'!D37,'P&Ls Summary'!$D$9:$D$40,0)) -> #DIV/0! | F37: =E37*(1+$Q37) -> #DIV/0! | G37: =F37*(1+$Q37) -> #DIV/0! | H37: =G37*(1+$Q37) -> #DIV/0! | I37: =H37*(1+$Q37) -> #DIV/0! | J37: =I37*(1+$Q37) -> #DIV/0! | K37: =J37*(1+$Q37) -> #DIV/0! | L37: =K37*(1+$Q37) -> #DIV/0! | M37: =L37*(1+$Q37) -> #DIV/0! | N37: =M37*(1+$Q37) -> #DIV/0! | Q37: 0
D38: Total Operating Expenses | E38: =SUM(E25:E37) -> #DIV/0! | F38: =SUM(F25:F37) -> #DIV/0! | G38: =SUM(G25:G37) -> #DIV/0! | H38: =SUM(H25:H37) -> #DIV/0! | I38: =SUM(I25:I37) -> #DIV/0! | J38: =SUM(J25:J37) -> #DIV/0! | K38: =SUM(K25:K37) -> #DIV/0! | L38: =SUM(L25:L37) -> #DIV/0! | ... N38: =SUM(N25:N37) -> #DIV/0!
D39: Net Operating Income | E39: =E22-E38 -> #DIV/0! | F39: =F22-F38 -> #DIV/0! | G39: =G22-G38 -> #DIV/0! | H39: =H22-H38 -> #DIV/0! | I39: =I22-I38 -> #DIV/0! | J39: =J22-J38 -> #DIV/0! | K39: =K22-K38 -> #DIV/0! | L39: =L22-L38 -> #DIV/0! | ... N39: =N22-N38 -> #DIV/0!
D43: Market Rent | F43: =F8/E8-1 -> #DIV/0! | G43: =G8/F8-1 -> #DIV/0! | H43: =H8/G8-1 -> #DIV/0! | I43: =I8/H8-1 -> #DIV/0! | J43: =J8/I8-1 -> #DIV/0! | K43: =K8/J8-1 -> #DIV/0! | L43: =L8/K8-1 -> #DIV/0! | M43: =M8/L8-1 -> #DIV/0! | N43: =N8/M8-1 -> #DIV/0!
D44: LTL | E44: =IF(E5>$T$9,"",E9/$E$9) -> #DIV/0! | F44: =IF(F5>$T$9,"",F9/$E$9) -> #DIV/0! | G44: =IF(G5>$T$9,"",G9/$E$9) -> #DIV/0! | H44: =IF(H5>$T$9,"",H9/$E$9) -> #DIV/0! | I44: =IF(I5>$T$9,"",I9/$E$9) | J44: =IF(J5>$T$9,"",J9/$E$9) | K44: =IF(K5>$T$9,"",K9/$E$9) | L44: =IF(L5>$T$9,"",L9/$E$9) | ... N44: =IF(N5>$T$9,"",N9/$E$9)
D45: Gross Rental Income | F45: =F10/E10-1 -> #DIV/0! | G45: =G10/F10-1 -> #DIV/0! | H45: =H10/G10-1 -> #DIV/0! | I45: =I10/H10-1 -> #DIV/0! | J45: =J10/I10-1 -> #DIV/0! | K45: =K10/J10-1 -> #DIV/0! | L45: =L10/K10-1 -> #DIV/0! | M45: =M10/L10-1 -> #DIV/0! | N45: =N10/M10-1 -> #DIV/0!
D46: EGI | F46: =F22/E22-1 -> #DIV/0! | G46: =G22/F22-1 -> #DIV/0! | H46: =H22/G22-1 -> #DIV/0! | I46: =I22/H22-1 -> #DIV/0! | J46: =J22/I22-1 -> #DIV/0! | K46: =K22/J22-1 -> #DIV/0! | L46: =L22/K22-1 -> #DIV/0! | M46: =M22/L22-1 -> #DIV/0! | N46: =N22/M22-1 -> #DIV/0!
D47: OpEx | F47: =F38/E38-1 -> #DIV/0! | G47: =G38/F38-1 -> #DIV/0! | H47: =H38/G38-1 -> #DIV/0! | I47: =I38/H38-1 -> #DIV/0! | J47: =J38/I38-1 -> #DIV/0! | K47: =K38/J38-1 -> #DIV/0! | L47: =L38/K38-1 -> #DIV/0! | M47: =M38/L38-1 -> #DIV/0! | N47: =N38/M38-1 -> #DIV/0!
D48: NOI | F48: =F39/E39-1 -> #DIV/0! | G48: =G39/F39-1 -> #DIV/0! | H48: =H39/G39-1 -> #DIV/0! | I48: =I39/H39-1 -> #DIV/0! | J48: =J39/I39-1 -> #DIV/0! | K48: =K39/J39-1 -> #DIV/0! | L48: =L39/K39-1 -> #DIV/0! | M48: =M39/L39-1 -> #DIV/0! | N48: =N39/M39-1 -> #DIV/0!
...

Sheet P&Ls Detailed
C3: DETAILED INCOME STATEMENT | AB3: ='Exec Summ'!F6 -> Hudson View Park | AD3: ='P&Ls Summary'!AA3 -> 0 | AE3: =IF(COUNTIF(AF155:AR157,"False")=0,"OK","ERROR") -> OK
D5: Property | E5: General CoA | F5: Exc. In IP NOI? | G5: Seller's CoA | H5: 45443 | I5: =EOMONTH(H5,1) -> 45473 | J5: =EOMONTH(I5,1) -> 45504 | K5: =EOMONTH(J5,1) -> 45535 | L5: =EOMONTH(K5,1) -> 45565 | M5: =EOMONTH(L5,1) -> 45596 | N5: =EOMONTH(M5,1) -> 45626 | O5: =EOMONTH(N5,1) -> 45657 | P5: =EOMONTH(O5,1) -> 45688 | ... S5: =EOMONTH(R5,1) -> 45777 | T5: YE 2022 | U5: YE 2023 | V5: YE 2024 | W5: ="T-12"&CHAR(10)&TEXT($H$5,"(mm.yy"&"-")&TEXT($S$5,"mm.yy)") -> T-12 (05.24-04.25) | X5: ="T-9 Ann."&CHAR(10)&TEXT($K$5,"(mm.yy"&"-")&TEXT($S$5,"mm.yy)") -> T-9 Ann. (08.24-04.25) | Y5: ="T-6 Ann."&CHAR(10)&TEXT($N$5,"(mm.yy"&"-")&TEXT($S$5,"mm.yy)") -> T-6 Ann. (11.24-04.25) | Z5: ="T-3 Ann."&CHAR(10)&TEXT($Q$5,"(mm.yy"&"-")&TEXT($S$5,"mm.yy)") -> T-3 Ann. (02.25-04.25) | AA5: ="T-1 Ann."&CHAR(10)&TEXT($S$5,"(mm.yy"&"-")&TEXT($S$5,"mm.yy)") -> T-1 Ann. (04.25-04.25)
D7: =$AB$3 -> Hudson View Park | G7: Operating Income & Expense
D8: =$AB$3 -> Hudson View Park | G8: Income
D9: =$AB$3 -> Hudson View Park | G9: EFFECTIVE RENTAL REVENUE
