Workbook

Sheet Instructions
A1: Multifamily UW Model — Starter Template (v2)
A3: How to use
A4: Legend | B4: BLUE = your input / scenario lever • YELLOW = key assumption to fill in • BLACK = formula (don't overwrite) • GREEN = pulls from another tab.
A5: Fill order | B5: 1) Assumptions 2) RR (rent roll) 3) Renovation (value-add scope & timing) 4) P&L (enter in-place expenses) 5) review Pro Forma / Debt / Returns / Sensitivity (all auto-calc).
A7: HOW THE TABS CONNECT (one chain)
A8: Assumptions | B8: Control panel. Every lever lives here once — growth, vacancy, cap rates, LTV, rate, and HOLD PERIOD (1-10 yrs; the model exits automatically in the hold year). Change a deal from this one tab.
A9: RR (Rent Roll) | B9: Unit-level income engine. Unit mix x in-place rent = in-place GPR; unit mix x market rent = as-is market GPR. Feeds the P&L top line and the unit count.
A10: Renovation (value-add) | B10: The value-add engine. Per unit type: how many units you renovate, the cost/unit, and the rent premium/unit achieved ABOVE market. Sums to a total renovation budget (-> Sources & Uses) and a rent-premium schedule phased by your completion %/year (-> Pro Forma). Capex is funded upfront in the capital stack; the timing row shows when the budget is drawn and when the premium is earned.
A11: P&L (Operating Statement) | B11: Turns rent into cash flow. GPR (from RR) - vacancy & bad debt + other income = EGI; EGI - operating expenses = NOI. Two columns: In-Place (T-12 you type) and Year-1 Underwritten (as-is market). NOI is the single most important number.
A12: Pro Forma (10-yr) | B12: Projects Year-1 underwritten EGI & OpEx across up to 10 years using the growth rates, then LAYERS ON the renovation premium schedule -> NOI each year.
A13: Sources & Uses | B13: Capital stack. Uses = price + closing + renovation budget (from Renovation). Sources = senior loan (LTV x price) + equity (the plug). Equity anchors returns.
A14: Debt | B14: Sizes & amortizes the loan: annual debt service, DSCR, debt yield, and the loan payoff balance in the hold year.
A15: Returns | B15: Ties it together, exiting in your chosen hold year: levered CF = Pro Forma NOI - debt service; exit value = hold-year NOI / exit cap; proceeds repay the loan -> IRR, equity multiple, cash-on-cash (levered & unlevered).
A16: Sensitivity | B16: A 2-way grid of levered IRR across Exit Cap (columns) x Rent Growth (rows). It re-runs the full levered cash flow for each combination via backing calcs below the grid, so it updates live when you change the deal. The center cell equals the Returns tab IRR.
A18: One sentence | B18: RR + Renovation build income -> P&L converts it to NOI -> Pro Forma grows & renovates NOI over the hold -> Sources & Uses and Debt set the capital -> Returns measures the equity's IRR -> Sensitivity stress-tests it.
A20: Renovation funding note | B20: The renovation budget is included in Uses and funded at close (equity + loan), so it is NOT subtracted again from operating cash flow. The Renovation timing row is informational (draw schedule) and drives WHEN the rent premium is realized.
A21: Note | B21: Teaching/starter template with illustrative numbers (a ~100-unit value-add deal). Replace every blue/yellow cell with your deal's data. Not investment advice.

Sheet Assumptions
A1: Assumptions (control panel — edit here)
A3: PROPERTY & ACQUISITION
A4: Purchase Price | B4: 16000000 | C4: Fill in the yellow cells for your deal.
A5: Number of Units | B5: ='RR'!$B$8
A6: Price per Unit | B6: =B4/B5
A7: Going-in Cap (as-is, Yr1 UW) | B7: ='P&L'!$C$24/B4 | C7: Auto: Year-1 as-is underwritten NOI / price (excludes reno upside).
A8: Hold Period (years, 1-10) | B8: 7 | C8: Model exits automatically in this year (max 10).
A9: Exit Cap Rate | B9: 0.06 | C9: Exit cap usually >= going-in cap (be conservative).
A10: Selling Costs (% of sale) | B10: 0.02
A11: Closing Costs (% of price) | B11: 0.02
A13: GROWTH & OPERATING
A14: Revenue Growth (annual) | B14: 0.03
A15: Expense Growth (annual) | B15: 0.03
A16: Economic Vacancy | B16: 0.05
A17: Bad Debt & Concessions | B17: 0.01
A18: Management Fee (% of EGI) | B18: 0.03
A19: Replacement Reserves ($/unit/yr) | B19: 250
A21: FINANCING
A22: Loan-to-Value (LTV) | B22: 0.65 | C22: Loan = LTV x purchase price (see Sources & Uses).
A23: Interest Rate | B23: 0.065
A24: Amortization (years) | B24: 30
A25: Renovation Budget (auto) | B25: ='Renovation'!$E$9 | C25: Totals up from the Renovation tab scope.

Sheet RR
A1: RR — Rent Roll (unit-level income engine)
A3: Unit Type | B3: # Units | C3: Avg SF | D3: In-Place Rent ($/unit/mo) | E3: Market Rent ($/unit/mo) | F3: In-Place Monthly | G3: In-Place Annual | H3: Market Monthly | I3: Market Annual
A4: 1 BD / 1 BA | B4: 40 | C4: 700 | D4: 1150 | E4: 1300 | F4: =B4*D4 | G4: =F4*12 | H4: =B4*E4 | I4: =H4*12
A5: 2 BD / 1 BA | B5: 30 | C5: 950 | D5: 1400 | E5: 1575 | F5: =B5*D5 | G5: =F5*12 | H5: =B5*E5 | I5: =H5*12
A6: 2 BD / 2 BA | B6: 20 | C6: 1050 | D6: 1550 | E6: 1725 | F6: =B6*D6 | G6: =F6*12 | H6: =B6*E6 | I6: =H6*12
A7: 3 BD / 2 BA | B7: 10 | C7: 1250 | D7: 1850 | E7: 2050 | F7: =B7*D7 | G7: =F7*12 | H7: =B7*E7 | I7: =H7*12
A8: Total / Weighted | B8: =SUM(B4:B7) | C8: =SUMPRODUCT(B4:B7,C4:C7)/B8 | D8: =F8/B8 | E8: =H8/B8 | F8: =SUM(F4:F7) | G8: =SUM(G4:G7) | H8: =SUM(H4:H7) | I8: =SUM(I4:I7)
A10: Loss-to-Lease (Market - In-Place, annual) | I10: =I8-G8

Sheet Renovation
A1: Renovation — value-add scope, budget & timing
A3: RENOVATION SCOPE (by unit type)
A4: Unit Type | B4: # Units to Reno | C4: Reno Cost/Unit | D4: Rent Premium ($/mo) | E4: Reno Budget | F4: Annual Premium (gross)
A5: 1 BD / 1 BA | B5: 25 | C5: 12000 | D5: 150 | E5: =B5*C5 | F5: =B5*D5*12
A6: 2 BD / 1 BA | B6: 20 | C6: 14000 | D6: 175 | E6: =B6*C6 | F6: =B6*D6*12
A7: 2 BD / 2 BA | B7: 10 | C7: 15000 | D7: 200 | E7: =B7*C7 | F7: =B7*D7*12
A8: 3 BD / 2 BA | B8: 5 | C8: 18000 | D8: 225 | E8: =B8*C8 | F8: =B8*D8*12
A9: Total | B9: =SUM(B5:B8) | E9: =SUM(E5:E8) | F9: =SUM(F5:F8)
A10: Blended cost / renovated unit | E10: =E9/B9
A12: RENOVATION TIMING (phased)
A13: Year | B13: 1 | C13: 2 | D13: 3 | E13: 4 | F13: 5 | G13: 6 | H13: 7 | I13: 8 | J13: 9 | K13: 10
A14: % of Scope Complete (cumulative) | B14: 0.4 | C14: 0.8 | D14: 1 | E14: 1 | F14: 1 | G14: 1 | H14: 1 | I14: 1 | J14: 1 | K14: 1
A15: Cumulative Units Renovated | B15: =$B$9*B14 | C15: =$B$9*C14 | D15: =$B$9*D14 | E15: =$B$9*E14 | F15: =$B$9*F14 | G15: =$B$9*G14 | H15: =$B$9*H14 | I15: =$B$9*I14 | ... K15: =$B$9*K14
A16: Reno Capex Draw ($) | B16: =$E$9*B14 | C16: =$E$9*(C14-B14) | D16: =$E$9*(D14-C14) | E16: =$E$9*(E14-D14) | F16: =$E$9*(F14-E14) | G16: =$E$9*(G14-F14) | H16: =$E$9*(H14-G14) | I16: =$E$9*(I14-H14) | J16: =$E$9*(J14-I14) | K16: =$E$9*(K14-J14)
A17: Cumulative Premium (gross annual) | B17: =$F$9*B14 | C17: =$F$9*C14 | D17: =$F$9*D14 | E17: =$F$9*E14 | F17: =$F$9*F14 | G17: =$F$9*G14 | H17: =$F$9*H14 | I17: =$F$9*I14 | ... K17: =$F$9*K14
A18: Net Premium to EGI | B18: =B17*(1-'Assumptions'!$B$16-'Assumptions'!$B$17) | C18: =C17*(1-'Assumptions'!$B$16-'Assumptions'!$B$17) | D18: =D17*(1-'Assumptions'!$B$16-'Assumptions'!$B$17) | E18: =E17*(1-'Assumptions'!$B$16-'Assumptions'!$B$17) | F18: =F17*(1-'Assumptions'!$B$16-'Assumptions'!$B$17) | G18: =G17*(1-'Assumptions'!$B$16-'Assumptions'!$B$17) | H18: =H17*(1-'Assumptions'!$B$16-'Assumptions'!$B$17) | I18: =I17*(1-'Assumptions'!$B$16-'Assumptions'!$B$17) | ... K18: =K17*(1-'Assumptions'!$B$16-'Assumptions'!$B$17)

Sheet P&L
A1: P&L — Operating Statement (income -> NOI)
A3: Line Item | B3: In-Place (T-12) | C3: Year-1 Underwritten | D3: Per Unit (UW) | E3: Notes
A4: INCOME
A5: Gross Potential Rent (GPR) | B5: 'RR'!$G$8 | C5: 'RR'!$I$8 | D5: =C5/'RR'!$B$8 | E5: In-place=RR in-place annual; UW=RR as-is market annual.
A6: Less: Vacancy | B6: =-B5*'Assumptions'!$B$16 | C6: =-C5*'Assumptions'!$B$16 | D6: =C6/'RR'!$B$8 | E6: Economic vacancy.
A7: Less: Bad Debt & Concessions | B7: =-B5*'Assumptions'!$B$17 | C7: =-C5*'Assumptions'!$B$17 | D7: =C7/'RR'!$B$8
A8: Net Rental Income | B8: =SUM(B5:B7) | C8: =SUM(C5:C7) | D8: =C8/'RR'!$B$8
A9: Other Income (RUBS, fees, laundry) | B9: 90000 | C9: =B9*(1+'Assumptions'!$B$14) | D9: =C9/'RR'!$B$8 | E9: Type T-12 actual; UW grows it one year.
A10: Effective Gross Income (EGI) | B10: =B8+B9 | C10: =C8+C9 | D10: =C10/'RR'!$B$8
A12: OPERATING EXPENSES
A13: Property Taxes | B13: 165000 | C13: =B13*(1+'Assumptions'!$B$15) | D13: =C13/'RR'!$B$8
A14: Insurance | B14: 55000 | C14: =B14*(1+'Assumptions'!$B$15) | D14: =C14/'RR'!$B$8
A15: Utilities | B15: 120000 | C15: =B15*(1+'Assumptions'!$B$15) | D15: =C15/'RR'!$B$8
A16: Repairs & Maintenance | B16: 95000 | C16: =B16*(1+'Assumptions'!$B$15) | D16: =C16/'RR'!$B$8
A17: Payroll | B17: 140000 | C17: =B17*(1+'Assumptions'!$B$15) | D17: =C17/'RR'!$B$8
A18: Contract Services | B18: 45000 | C18: =B18*(1+'Assumptions'!$B$15) | D18: =C18/'RR'!$B$8
A19: Marketing & Leasing | B19: 20000 | C19: =B19*(1+'Assumptions'!$B$15) | D19: =C19/'RR'!$B$8
A20: General & Admin | B20: 30000 | C20: =B20*(1+'Assumptions'!$B$15) | D20: =C20/'RR'!$B$8
A21: Management Fee (% of EGI) | B21: =B10*'Assumptions'!$B$18 | C21: =C10*'Assumptions'!$B$18 | D21: =C21/'RR'!$B$8 | E21: Computed as % of EGI.
A22: Replacement Reserves | B22: ='RR'!$B$8*'Assumptions'!$B$19 | C22: ='RR'!$B$8*'Assumptions'!$B$19 | D22: =C22/'RR'!$B$8 | E22: Units x reserves/unit.
A23: Total Operating Expenses | B23: =SUM(B13:B22) | C23: =SUM(C13:C22) | D23: =C23/'RR'!$B$8
A24: NET OPERATING INCOME (NOI) | B24: =B10-B23 | C24: =C10-C23 | D24: =C24/'RR'!$B$8
A25: Operating Expense Ratio | B25: =B23/B10 | C25: =C23/C10

Sheet Pro Forma
A1: Pro Forma — NOI projection over the hold (up to 10 yrs)
A3: Line Item | B3: Year 1 | C3: Year 2 | D3: Year 3 | E3: Year 4 | F3: Year 5 | G3: Year 6 | H3: Year 7 | I3: Year 8 | J3: Year 9 | K3: Year 10
A4: Base EGI (organic) | B4: ='P&L'!$C$10 | C4: =B4*(1+'Assumptions'!$B$14) | D4: =C4*(1+'Assumptions'!$B$14) | E4: =D4*(1+'Assumptions'!$B$14) | F4: =E4*(1+'Assumptions'!$B$14) | G4: =F4*(1+'Assumptions'!$B$14) | H4: =G4*(1+'Assumptions'!$B$14) | I4: =H4*(1+'Assumptions'!$B$14) | J4: =I4*(1+'Assumptions'!$B$14) | K4: =J4*(1+'Assumptions'!$B$14)
A5: + Renovation Premium (net) | B5: ='Renovation'!B18 | C5: ='Renovation'!C18 | D5: ='Renovation'!D18 | E5: ='Renovation'!E18 | F5: ='Renovation'!F18 | G5: ='Renovation'!G18 | H5: ='Renovation'!H18 | I5: ='Renovation'!I18 | ... K5: ='Renovation'!K18
A6: Effective Gross Income | B6: =B4+B5 | C6: =C4+C5 | D6: =D4+D5 | E6: =E4+E5 | F6: =F4+F5 | G6: =G4+G5 | H6: =H4+H5 | I6: =I4+I5 | ... K6: =K4+K5
A7: Operating Expenses | B7: ='P&L'!$C$23 | C7: =B7*(1+'Assumptions'!$B$15) | D7: =C7*(1+'Assumptions'!$B$15) | E7: =D7*(1+'Assumptions'!$B$15) | F7: =E7*(1+'Assumptions'!$B$15) | G7: =F7*(1+'Assumptions'!$B$15) | H7: =G7*(1+'Assumptions'!$B$15) | I7: =H7*(1+'Assumptions'!$B$15) | J7: =I7*(1+'Assumptions'!$B$15) | K7: =J7*(1+'Assumptions'!$B$15)
A8: Net Operating Income | B8: =B6-B7 | C8: =C6-C7 | D8: =D6-D7 | E8: =E6-E7 | F8: =F6-F7 | G8: =G6-G7 | H8: =H6-H7 | I8: =I6-I7 | ... K8: =K6-K7
A9: NOI Growth % | B9: — | C9: =C8/B8-1 | D9: =D8/C8-1 | E9: =E8/D8-1 | F9: =F8/E8-1 | G9: =G8/F8-1 | H9: =H8/G8-1 | I9: =I8/H8-1 | J9: =J8/I8-1 | K9: =K8/J8-1
A10: (memo) Reno Capex Draw | B10: ='Renovation'!B16 | C10: ='Renovation'!C16 | D10: ='Renovation'!D16 | E10: ='Renovation'!E16 | F10: ='Renovation'!F16 | G10: ='Renovation'!G16 | H10: ='Renovation'!H16 | I10: ='Renovation'!I16 | ... K10: ='Renovation'!K16

Sheet Sources & Uses
A1: Sources & Uses — capital stack
A3: USES OF FUNDS
A4: Purchase Price | B4: ='Assumptions'!$B$4
A5: Closing Costs | B5: ='Assumptions'!$B$4*'Assumptions'!$B$11
A6: Renovation Budget | B6: ='Renovation'!$E$9
A7: Total Uses | B7: =SUM(B4:B6)
A9: SOURCES OF FUNDS
A10: Senior Loan | B10: ='Assumptions'!$B$4*'Assumptions'!$B$22 | C10: =B10/B7 | D10: =LTV x Purchase Price
A11: Equity (plug) | B11: =B7-B10 | C11: =B11/B7 | D11: =the equity check the investor writes
A12: Total Sources | B12: =SUM(B10:B11)
A14: Check (Sources - Uses) | B14: =B12-B7

Sheet Debt
A1: Debt — loan sizing & amortization
A4: Loan Amount | B4: ='Sources & Uses'!$B$10 | C4: From Sources & Uses.
A5: Interest Rate | B5: ='Assumptions'!$B$23
A6: Amortization (years) | B6: ='Assumptions'!$B$24
A7: Hold Period (years) | B7: ='Assumptions'!$B$8
A8: Monthly Payment | B8: =PMT(B5/12,B6*12,-B4) | C8: Standard amortizing payment.
A9: Annual Debt Service | B9: =B8*12
A10: DSCR (Year-1 NOI) | B10: ='Pro Forma'!$B$8/B9 | C10: NOI / debt service. Lenders want >= ~1.25x.
A11: Debt Yield (Year-1 NOI) | B11: ='Pro Forma'!$B$8/B4 | C11: NOI / loan.
A12: Loan Balance at Exit | B12: =B8*(1-(1+B5/12)^-(B6*12-B7*12))/(B5/12) | C12: Remaining principal in the hold year.

Sheet Returns
A1: Returns — levered & unlevered (exits in the hold year)
A3: Line Item | B3: Year 0 | C3: Year 1 | D3: Year 2 | E3: Year 3 | F3: Year 4 | G3: Year 5 | H3: Year 6 | I3: Year 7 | J3: Year 8 | K3: Year 9 | L3: Year 10
A4: Year # | B4: 0 | C4: 1 | D4: 2 | E4: 3 | F4: 4 | G4: 5 | H4: 6 | I4: 7 | J4: 8 | K4: 9 | L4: 10
A5: NOI (from Pro Forma) | C5: =IF(AND(C$4>=1,C$4<='Assumptions'!$B$8),'Pro Forma'!B8,0) | D5: =IF(AND(D$4>=1,D$4<='Assumptions'!$B$8),'Pro Forma'!C8,0) | E5: =IF(AND(E$4>=1,E$4<='Assumptions'!$B$8),'Pro Forma'!D8,0) | F5: =IF(AND(F$4>=1,F$4<='Assumptions'!$B$8),'Pro Forma'!E8,0) | G5: =IF(AND(G$4>=1,G$4<='Assumptions'!$B$8),'Pro Forma'!F8,0) | H5: =IF(AND(H$4>=1,H$4<='Assumptions'!$B$8),'Pro Forma'!G8,0) | I5: =IF(AND(I$4>=1,I$4<='Assumptions'!$B$8),'Pro Forma'!H8,0) | J5: =IF(AND(J$4>=1,J$4<='Assumptions'!$B$8),'Pro Forma'!I8,0) | ... L5: =IF(AND(L$4>=1,L$4<='Assumptions'!$B$8),'Pro Forma'!K8,0)
A6: Debt Service | C6: =IF(AND(C$4>=1,C$4<='Assumptions'!$B$8),-'Debt'!$B$9,0) | D6: =IF(AND(D$4>=1,D$4<='Assumptions'!$B$8),-'Debt'!$B$9,0) | E6: =IF(AND(E$4>=1,E$4<='Assumptions'!$B$8),-'Debt'!$B$9,0) | F6: =IF(AND(F$4>=1,F$4<='Assumptions'!$B$8),-'Debt'!$B$9,0) | G6: =IF(AND(G$4>=1,G$4<='Assumptions'!$B$8),-'Debt'!$B$9,0) | H6: =IF(AND(H$4>=1,H$4<='Assumptions'!$B$8),-'Debt'!$B$9,0) | I6: =IF(AND(I$4>=1,I$4<='Assumptions'!$B$8),-'Debt'!$B$9,0) | J6: =IF(AND(J$4>=1,J$4<='Assumptions'!$B$8),-'Debt'!$B$9,0) | ... L6: =IF(AND(L$4>=1,L$4<='Assumptions'!$B$8),-'Debt'!$B$9,0)
A7: Operating CF (levered) | C7: =C5+C6 | D7: =D5+D6 | E7: =E5+E6 | F7: =F5+F6 | G7: =G5+G6 | H7: =H5+H6 | I7: =I5+I6 | J7: =J5+J6 | ... L7: =L5+L6
A8: Gross Sale Price (exit) | C8: =IF(C$4='Assumptions'!$B$8,C5/'Assumptions'!$B$9,0) | D8: =IF(D$4='Assumptions'!$B$8,D5/'Assumptions'!$B$9,0) | E8: =IF(E$4='Assumptions'!$B$8,E5/'Assumptions'!$B$9,0) | F8: =IF(F$4='Assumptions'!$B$8,F5/'Assumptions'!$B$9,0) | G8: =IF(G$4='Assumptions'!$B$8,G5/'Assumptions'!$B$9,0) | H8: =IF(H$4='Assumptions'!$B$8,H5/'Assumptions'!$B$9,0) | I8: =IF(I$4='Assumptions'!$B$8,I5/'Assumptions'!$B$9,0) | J8: =IF(J$4='Assumptions'!$B$8,J5/'Assumptions'!$B$9,0) | ... L8: =IF(L$4='Assumptions'!$B$8,L5/'Assumptions'!$B$9,0)
A9: Less: Selling Costs | C9: =-C8*'Assumptions'!$B$10 | D9: =-D8*'Assumptions'!$B$10 | E9: =-E8*'Assumptions'!$B$10 | F9: =-F8*'Assumptions'!$B$10 | G9: =-G8*'Assumptions'!$B$10 | H9: =-H8*'Assumptions'!$B$10 | I9: =-I8*'Assumptions'!$B$10 | J9: =-J8*'Assumptions'!$B$10 | ... L9: =-L8*'Assumptions'!$B$10
A10: Less: Loan Payoff | C10: =IF(C$4='Assumptions'!$B$8,-'Debt'!$B$12,0) | D10: =IF(D$4='Assumptions'!$B$8,-'Debt'!$B$12,0) | E10: =IF(E$4='Assumptions'!$B$8,-'Debt'!$B$12,0) | F10: =IF(F$4='Assumptions'!$B$8,-'Debt'!$B$12,0) | G10: =IF(G$4='Assumptions'!$B$8,-'Debt'!$B$12,0) | H10: =IF(H$4='Assumptions'!$B$8,-'Debt'!$B$12,0) | I10: =IF(I$4='Assumptions'!$B$8,-'Debt'!$B$12,0) | J10: =IF(J$4='Assumptions'!$B$8,-'Debt'!$B$12,0) | ... L10: =IF(L$4='Assumptions'!$B$8,-'Debt'!$B$12,0)
A11: Net Sale Proceeds | C11: =C8+C9+C10 | D11: =D8+D9+D10 | E11: =E8+E9+E10 | F11: =F8+F9+F10 | G11: =G8+G9+G10 | H11: =H8+H9+H10 | I11: =I8+I9+I10 | J11: =J8+J9+J10 | ... L11: =L8+L9+L10
A12: Net Levered Cash Flow | B12: =-'Sources & Uses'!$B$11 | C12: =C7+C11 | D12: =D7+D11 | E12: =E7+E11 | F12: =F7+F11 | G12: =G7+G11 | H12: =H7+H11 | I12: =I7+I11 | J12: =J7+J11 | ... L12: =L7+L11
A13: Net Unlevered Cash Flow | B13: =-'Sources & Uses'!$B$7 | C13: =C5+C8+C9 | D13: =D5+D8+D9 | E13: =E5+E8+E9 | F13: =F5+F8+F9 | G13: =G5+G8+G9 | H13: =H5+H8+H9 | I13: =I5+I8+I9 | J13: =J5+J8+J9 | ... L13: =L5+L8+L9
A15: RETURN METRICS
A16: Levered IRR | B16: =IRR(B12:L12) | D16: Annualized return to equity.
A17: Levered Equity Multiple | B17: =SUM(C12:L12)/'Sources & Uses'!$B$11 | D17: Total cash returned / equity in.
A18: Avg Cash-on-Cash (levered) | B18: =SUM(C7:L7)/'Assumptions'!$B$8/'Sources & Uses'!$B$11 | D18: Avg annual operating CF / equity over the hold.
A19: Unlevered IRR | B19: =IRR(B13:L13)
A20: Unlevered Equity Multiple | B20: =SUM(C13:L13)/'Sources & Uses'!$B$7
A21: Going-in Cap (as-is) | B21: ='Assumptions'!$B$7
A22: Exit Cap | B22: ='Assumptions'!$B$9
A23: Hold Period (yrs) | B23: ='Assumptions'!$B$8

Sheet Sensitivity
A1: Sensitivity — Levered IRR: Exit Cap (cols) x Rent Growth (rows)
B5: Growth \ Exit Cap | C5: 0.05 | D5: 0.055 | E5: 0.06 | F5: 0.065 | G5: 0.07
B6: 0.01 | C6: =B$33 | D6: =C$33 | E6: =D$33 | F6: =E$33 | G6: =F$33
B7: 0.02 | C7: =G$33 | D7: =H$33 | E7: =I$33 | F7: =J$33 | G7: =K$33
B8: 0.03 | C8: =L$33 | D8: =M$33 | E8: =N$33 | F8: =O$33 | G8: =P$33
B9: 0.04 | C9: =Q$33 | D9: =R$33 | E9: =S$33 | F9: =T$33 | G9: =U$33
B10: 0.05 | C10: =V$33 | D10: =W$33 | E10: =X$33 | F10: =Y$33 | G10: =Z$33
B12: Center cell (3% / 6.0%) = Returns levered IRR. Green shading is your base case.
A19: BACKING CALCULATIONS (do not edit) — one column per scenario
A20: Rent Growth (g) | B20: =$B$6 | C20: =$B$6 | D20: =$B$6 | E20: =$B$6 | F20: =$B$6 | G20: =$B$7 | H20: =$B$7 | I20: =$B$7 | J20: =$B$7 | K20: =$B$7 | L20: =$B$8 | M20: =$B$8 | N20: =$B$8 | O20: =$B$8 | P20: =$B$8 | Q20: =$B$9 | R20: =$B$9 | S20: =$B$9 | T20: =$B$9 | U20: =$B$9 | V20: =$B$10 | W20: =$B$10 | X20: =$B$10 | Y20: =$B$10 | Z20: =$B$10
A21: Exit Cap (X) | B21: =C$5 | C21: =D$5 | D21: =E$5 | E21: =F$5 | F21: =G$5 | G21: =C$5 | H21: =D$5 | I21: =E$5 | J21: =F$5 | K21: =G$5 | L21: =C$5 | M21: =D$5 | N21: =E$5 | O21: =F$5 | P21: =G$5 | Q21: =C$5 | R21: =D$5 | S21: =E$5 | T21: =F$5 | U21: =G$5 | V21: =C$5 | W21: =D$5 | X21: =E$5 | Y21: =F$5 | Z21: =G$5
A22: CF Year 0 | B22: =-'Sources & Uses'!$B$11 | C22: =-'Sources & Uses'!$B$11 | D22: =-'Sources & Uses'!$B$11 | E22: =-'Sources & Uses'!$B$11 | F22: =-'Sources & Uses'!$B$11 | G22: =-'Sources & Uses'!$B$11 | H22: =-'Sources & Uses'!$B$11 | I22: =-'Sources & Uses'!$B$11 | ... Z22: =-'Sources & Uses'!$B$11
A23: CF Year 1 | B23: =IF(1<='Assumptions'!$B$8,('P&L'!$C$10*(1+B$20)^0+'Renovation'!B$18-'P&L'!$C$23*(1+'Assumptions'!$B$15)^0)-'Debt'!$B$9,0)+IF(1='Assumptions'!$B$8,('P&L'!$C$10*(1+B$20)^0+'Renovation'!B$18-'P&L'!$C$23*(1+'Assumptions'!$B$15)^0)/B$21*(1-'Assumptions'!$B$10)-'Debt'!$B$12,0) | C23: =IF(1<='Assumptions'!$B$8,('P&L'!$C$10*(1+C$20)^0+'Renovation'!B$18-'P&L'!$C$23*(1+'Assumptions'!$B$15)^0)-'Debt'!$B$9,0)+IF(1='Assumptions'!$B$8,('P&L'!$C$10*(1+C$20)^0+'Renovation'!B$18-'P&L'!$C$23*(1+'Assumptions'!$B$15)^0)/C$21*(1-'Assumptions'!$B$10)-'Debt'!$B$12,0) | D23: =IF(1<='Assumptions'!$B$8,('P&L'!$C$10*(1+D$20)^0+'Renovation'!B$18-'P&L'!$C$23*(1+'Assumptions'!$B$15)^0)-'Debt'!$B$9,0)+IF(1='Assumptions'!$B$8,('P&L'!$C$10*(1+D$20)^0+'Renovation'!B$18-'P&L'!$C$23*(1+'Assumptions'!$B$15)^0)/D$21*(1-'Assumptions'!$B$10)-'Debt'!$B$12,0) | E23: =IF(1<='Assumptions'!$B$8,('P&L'!$C$10*(1+E$20)^0+'Renovation'!B$18-'P&L'!$C$23*(1+'Assumptions'!$B$15)^0)-'Debt'!$B$9,0)+IF(1='Assumptions'!$B$8,('P&L'!$C$10*(1+E$20)^0+'Renovation'!B$18-'P&L'!$C$23*(1+'Assumptions'!$B$15)^0)/E$21*(1-'Assumptions'!$B$10)-'Debt'!$B$12,0) | F23: =IF(1<='Assumptions'!$B$8,('P&L'!$C$10*(1+F$20)^0+'Renovation'!B$18-'P&L'!$C$23*(1+'Assumptions'!$B$15)^0)-'Debt'!$B$9,0)+IF(1='Assumptions'!$B$8,('P&L'!$C$10*(1+F$20)^0+'Renovation'!B$18-'P&L'!$C$23*(1+'Assumptions'!$B$15)^0)/F$21*(1-'Assumptions'!$B$10)-'Debt'!$B$12,0) | G23: =IF(1<='Assumptions'!$B$8,('P&L'!$C$10*(1+G$20)^0+'Renovation'!B$18-'P&L'!$C$23*(1+'Assumptions'!$B$15)^0)-'Debt'!$B$9,0)+IF(1='Assumptions'!$B$8,('P&L'!$C$10*(1+G$20)^0+'Renovation'!B$18-'P&L'!$C$23*(1+'Assumptions'!$B$15)^0)/G$21*(1-'Assumptions'!$B$10)-'Debt'!$B$12,0) | H23: =IF(1<='Assumptions'!$B$8,('P&L'!$C$10*(1+H$20)^0+'Renovation'!B$18-'P&L'!$C$23*(1+'Assumptions'!$B$15)^0)-'Debt'!$B$9,0)+IF(1='Assumptions'!$B$8,('P&L'!$C$10*(1+H$20)^0+'Renovation'!B$18-'P&L'!$C$23*(1+'Assumptions'!$B$15)^0)/H$21*(1-'Assumptions'!$B$10)-'Debt'!$B$12,0) | I23: =IF(1<='Assumptions'!$B$8,('P&L'!$C$10*(1+I$20)^0+'Renovation'!B$18-'P&L'!$C$23*(1+'Assumptions'!$B$15)^0)-'Debt'!$B$9,0)+IF(1='Assumptions'!$B$8,('P&L'!$C$10*(1+I$20)^0+'Renovation'!B$18-'P&L'!$C$23*(1+'Assumptions'!$B$15)^0)/I$21*(1-'Assumptions'!$B$10)-'Debt'!$B$12,0) | J23: =IF(1<='Assumptions'!$B$8,('P&L'!$C$10*(1+J$20)^0+'Renovation'!B$18-'P&L'!$C$23*(1+'Assumptions'!$B$15)^0)-'Debt'!$B$9,0)+IF(1='Assumptions'!$B$8,('P&L'!$C$10*(1+J$20)^0+'Renovation'!B$18-'P&L'!$C$23*(1+'Assumptions'!$B$15)^0)/J$21*(1-'Assumptions'!$B$10)-'Debt'!$B$12,0) | K23: =IF(1<='Assumptions'!$B$8,('P&L'!$C$10*(1+K$20)^0+'Renovation'!B$18-'P&L'!$C$23*(1+'Assumptions'!$B$15)^0)-'Debt'!$B$9,0)+IF(1='Assumptions'!$B$8,('P&L'!$C$10*(1+K$20)^0+'Renovation'!B$18-'P&L'!$C$23*(1+'Assumptions'!$B$15)^0)/K$21*(1-'Assumptions'!$B$10)-'Debt'!$B$12,0) | L23: =IF(1<='Assumptions'!$B$8,('P&L'!$C$10*(1+L$20)^0+'Renovation'!B$18-'P&L'!$C$23*(1+'Assumptions'!$B$15)^0)-'Debt'!$B$9,0)+IF(1='Assumptions'!$B$8,('P&L'!$C$10*(1+L$20)^0+'Renovation'!B$18-'P&L'!$C$23*(1+'Assumptions'!$B$15)^0)/L$21*(1-'Assumptions'!$B$10)-'Debt'!$B$12,0) | M23: =IF(1<='Assumptions'!$B$8,('P&L'!$C$10*(1+M$20)^0+'Renovation'!B$18-'P&L'!$C$23*(1+'Assumptions'!$B$15)^0)-'Debt'!$B$9,0)+IF(1='Assumptions'!$B$8,('P&L'!$C$10*(1+M$20)^0+'Renovation'!B$18-'P&L'!$C$23*(1+'Assumptions'!$B$15)^0)/M$21*(1-'Assumptions'!$B$10)-'Debt'!$B$12,0) | N23: =IF(1<='Assumptions'!$B$8,('P&L'!$C$10*(1+N$20)^0+'Renovation'!B$18-'P&L'!$C$23*(1+'Assumptions'!$B$15)^0)-'Debt'!$B$9,0)+IF(1='Assumptions'!$B$8,('P&L'!$C$10*(1+N$20)^0+'Renovation'!B$18-'P&L'!$C$23*(1+'Assumptions'!$B$15)^0)/N$21*(1-'Assumptions'!$B$10)-'Debt'!$B$12,0) | O23: =IF(1<='Assumptions'!$B$8,('P&L'!$C$10*(1+O$20)^0+'Renovation'!B$18-'P&L'!$C$23*(1+'Assumptions'!$B$15)^0)-'Debt'!$B$9,0)+IF(1='Assumptions'!$B$8,('P&L'!$C$10*(1+O$20)^0+'Renovation'!B$18-'P&L'!$C$23*(1+'Assumptions'!$B$15)^0)/O$21*(1-'Assumptions'!$B$10)-'Debt'!$B$12,0) | P23: =IF(1<='Assumptions'!$B$8,('P&L'!$C$10*(1+P$20)^0+'Renovation'!B$18-'P&L'!$C$23*(1+'Assumptions'!$B$15)^0)-'Debt'!$B$9,0)+IF(1='Assumptions'!$B$8,('P&L'!$C$10*(1+P$20)^0+'Renovation'!B$18-'P&L'!$C$23*(1+'Assumptions'!$B$15)^0)/P$21*(1-'Assumptions'!$B$10)-'Debt'!$B$12,0) | Q23: =IF(1<='Assumptions'!$B$8,('P&L'!$C$10*(1+Q$20)^0+'Renovation'!B$18-'P&L'!$C$23*(1+'Assumptions'!$B$15)^0)-'Debt'!$B$9,0)+IF(1='Assumptions'!$B$8,('P&L'!$C$10*(1+Q$20)^0+'Renovation'!B$18-'P&L'!$C$23*(1+'Assumptions'!$B$15)^0)/Q$21*(1-'Assumptions'!$B$10)-'Debt'!$B$12,0) | R23: =IF(1<='Assumptions'!$B$8,('P&L'!$C$10*(1+R$20)^0+'Renovation'!B$18-'P&L'!$C$23*(1+'Assumptions'!$B$15)^0)-'Debt'!$B$9,0)+IF(1='Assumptions'!$B$8,('P&L'!$C$10*(1+R$20)^0+'Renovation'!B$18-'P&L'!$C$23*(1+'Assumptions'!$B$15)^0)/R$21*(1-'Assumptions'!$B$10)-'Debt'!$B$12,0) | S23: =IF(1<='Assumptions'!$B$8,('P&L'!$C$10*(1+S$20)^0+'Renovation'!B$18-'P&L'!$C$23*(1+'Assumptions'!$B$15)^0)-'Debt'!$B$9,0)+IF(1='Assumptions'!$B$8,('P&L'!$C$10*(1+S$20)^0+'Renovation'!B$18-'P&L'!$C$23*(1+'Assumptions'!$B$15)^0)/S$21*(1-'Assumptions'!$B$10)-'Debt'!$B$12,0) | T23: =IF(1<='Assumptions'!$B$8,('P&L'!$C$10*(1+T$20)^0+'Renovation'!B$18-'P&L'!$C$23*(1+'Assumptions'!$B$15)^0)-'Debt'!$B$9,0)+IF(1='Assumptions'!$B$8,('P&L'!$C$10*(1+T$20)^0+'Renovation'!B$18-'P&L'!$C$23*(1+'Assumptions'!$B$15)^0)/T$21*(1-'Assumptions'!$B$10)-'Debt'!$B$12,0) | U23: =IF(1<='Assumptions'!$B$8,('P&L'!$C$10*(1+U$20)^0+'Renovation'!B$18-'P&L'!$C$23*(1+'Assumptions'!$B$15)^0)-'Debt'!$B$9,0)+IF(1='Assumptions'!$B$8,('P&L'!$C$10*(1+U$20)^0+'Renovation'!B$18-'P&L'!$C$23*(1+'Assumptions'!$B$15)^0)/U$21*(1-'Assumptions'!$B$10)-'Debt'!$B$12,0) | V23: =IF(1<='Assumptions'!$B$8,('P&L'!$C$10*(1+V$20)^0+'Renovation'!B$18-'P&L'!$C$23*(1+'Assumptions'!$B$15)^0)-'Debt'!$B$9,0)+IF(1='Assumptions'!$B$8,('P&L'!$C$10*(1+V$20)^0+'Renovation'!B$18-'P&L'!$C$23*(1+'Assumptions'!$B$15)^0)/V$21*(1-'Assumptions'!$B$10)-'Debt'!$B$12,0) | W23: =IF(1<='Assumptions'!$B$8,('P&L'!$C$10*(1+W$20)^0+'Renovation'!B$18-'P&L'!$C$23*(1+'Assumptions'!$B$15)^0)-'Debt'!$B$9,0)+IF(1='Assumptions'!$B$8,('P&L'!$C$10*(1+W$20)^0+'Renovation'!B$18-'P&L'!$C$23*(1+'Assumptions'!$B$15)^0)/W$21*(1-'Assumptions'!$B$10)-'Debt'!$B$12,0) | X23: =IF(1<='Assumptions'!$B$8,('P&L'!$C$10*(1+X$20)^0+'Renovation'!B$18-'P&L'!$C$23*(1+'Assumptions'!$B$15)^0)-'Debt'!$B$9,0)+IF(1='Assumptions'!$B$8,('P&L'!$C$10*(1+X$20)^0+'Renovation'!B$18-'P&L'!$C$23*(1+'Assumptions'!$B$15)^0)/X$21*(1-'Assumptions'!$B$10)-'Debt'!$B$12,0) | Y23: =IF(1<='Assumptions'!$B$8,('P&L'!$C$10*(1+Y$20)^0+'Renovation'!B$18-'P&L'!$C$23*(1+'Assumptions'!$B$15)^0)-'Debt'!$B$9,0)+IF(1='Assumptions'!$B$8,('P&L'!$C$10*(1+Y$20)^0+'Renovation'!B$18-'P&L'!$C$23*(1+'Assumptions'!$B$15)^0)/Y$21*(1-'Assumptions'!$B$10)-'Debt'!$B$12,0) | Z23: =IF(1<='Assumptions'!$B$8,('P&L'!$C$10*(1+Z$20)^0+'Renovation'!B$18-'P&L'!$C$23*(1+'Assumptions'!$B$15)^0)-'Debt'!$B$9,0)+IF(1='Assumptions'!$B$8,('P&L'!$C$10*(1+Z$20)^0+'Renovation'!B$18-'P&L'!$C$23*(1+'Assumptions'!$B$15)^0)/Z$21*(1-'Assumptions'!$B$10)-'Debt'!$B$12,0)
A24: CF Year 2 | B24: =IF(2<='Assumptions'!$B$8,('P&L'!$C$10*(1+B$20)^1+'Renovation'!C$18-'P&L'!$C$23*(1+'Assumptions'!$B$15)^1)-'Debt'!$B$9,0)+IF(2='Assumptions'!$B$8,('P&L'!$C$10*(1+B$20)^1+'Renovation'!C$18-'P&L'!$C$23*(1+'Assumptions'!$B$15)^1)/B$21*(1-'Assumptions'!$B$10)-'Debt'!$B$12,0) | C24: =IF(2<='Assumptions'!$B$8,('P&L'!$C$10*(1+C$20)^1+'Renovation'!C$18-'P&L'!$C$23*(1+'Assumptions'!$B$15)^1)-'Debt'!$B$9,0)+IF(2='Assumptions'!$B$8,('P&L'!$C$10*(1+C$20)^1+'Renovation'!C$18-'P&L'!$C$23*(1+'Assumptions'!$B$15)^1)/C$21*(1-'Assumptions'!$B$10)-'Debt'!$B$12,0) | D24: =IF(2<='Assumptions'!$B$8,('P&L'!$C$10*(1+D$20)^1+'Renovation'!C$18-'P&L'!$C$23*(1+'Assumptions'!$B$15)^1)-'Debt'!$B$9,0)+IF(2='Assumptions'!$B$8,('P&L'!$C$10*(1+D$20)^1+'Renovation'!C$18-'P&L'!$C$23*(1+'Assumptions'!$B$15)^1)/D$21*(1-'Assumptions'!$B$10)-'Debt'!$B$12,0) | E24: =IF(2<='Assumptions'!$B$8,('P&L'!$C$10*(1+E$20)^1+'Renovation'!C$18-'P&L'!$C$23*(1+'Assumptions'!$B$15)^1)-'Debt'!$B$9,0)+IF(2='Assumptions'!$B$8,('P&L'!$C$10*(1+E$20)^1+'Renovation'!C$18-'P&L'!$C$23*(1+'Assumptions'!$B$15)^1)/E$21*(1-'Assumptions'!$B$10)-'Debt'!$B$12,0) | F24: =IF(2<='Assumptions'!$B$8,('P&L'!$C$10*(1+F$20)^1+'Renovation'!C$18-'P&L'!$C$23*(1+'Assumptions'!$B$15)^1)-'Debt'!$B$9,0)+IF(2='Assumptions'!$B$8,('P&L'!$C$10*(1+F$20)^1+'Renovation'!C$18-'P&L'!$C$23*(1+'Assumptions'!$B$15)^1)/F$21*(1-'Assumptions'!$B$10)-'Debt'!$B$12,0) | G24: =IF(2<='Assumptions'!$B$8,('P&L'!$C$10*(1+G$20)^1+'Renovation'!C$18-'P&L'!$C$23*(1+'Assumptions'!$B$15)^1)-'Debt'!$B$9,0)+IF(2='Assumptions'!$B$8,('P&L'!$C$10*(1+G$20)^1+'Renovation'!C$18-'P&L'!$C$23*(1+'Assumptions'!$B$15)^1)/G$21*(1-'Assumptions'!$B$10)-'Debt'!$B$12,0) | H24: =IF(2<='Assumptions'!$B$8,('P&L'!$C$10*(1+H$20)^1+'Renovation'!C$18-'P&L'!$C$23*(1+'Assumptions'!$B$15)^1)-'Debt'!$B$9,0)+IF(2='Assumptions'!$B$8,('P&L'!$C$10*(1+H$20)^1+'Renovation'!C$18-'P&L'!$C$23*(1+'Assumptions'!$B$15)^1)/H$21*(1-'Assumptions'!$B$10)-'Debt'!$B$12,0) | I24: =IF(2<='Assumptions'!$B$8,('P&L'!$C$10*(1+I$20)^1+'Renovation'!C$18-'P&L'!$C$23*(1+'Assumptions'!$B$15)^1)-'Debt'!$B$9,0)+IF(2='Assumptions'!$B$8,('P&L'!$C$10*(1+I$20)^1+'Renovation'!C$18-'P&L'!$C$23*(1+'Assumptions'!$B$15)^1)/I$21*(1-'Assumptions'!$B$10)-'Debt'!$B$12,0) | J24: =IF(2<='Assumptions'!$B$8,('P&L'!$C$10*(1+J$20)^1+'Renovation'!C$18-'P&L'!$C$23*(1+'Assumptions'!$B$15)^1)-'Debt'!$B$9,0)+IF(2='Assumptions'!$B$8,('P&L'!$C$10*(1+J$20)^1+'Renovation'!C$18-'P&L'!$C$23*(1+'Assumptions'!$B$15)^1)/J$21*(1-'Assumptions'!$B$10)-'Debt'!$B$12,0) | K24: =IF(2<='Assumptions'!$B$8,('P&L'!$C$10*(1+K$20)^1+'Renovation'!C$18-'P&L'!$C$23*(1+'Assumptions'!$B$15)^1)-'Debt'!$B$9,0)+IF(2='Assumptions'!$B$8,('P&L'!$C$10*(1+K$20)^1+'Renovation'!C$18-'P&L'!$C$23*(1+'Assumptions'!$B$15)^1)/K$21*(1-'Assumptions'!$B$10)-'Debt'!$B$12,0) | L24: =IF(2<='Assumptions'!$B$8,('P&L'!$C$10*(1+L$20)^1+'Renovation'!C$18-'P&L'!$C$23*(1+'Assumptions'!$B$15)^1)-'Debt'!$B$9,0)+IF(2='Assumptions'!$B$8,('P&L'!$C$10*(1+L$20)^1+'Renovation'!C$18-'P&L'!$C$23*(1+'Assumptions'!$B$15)^1)/L$21*(1-'Assumptions'!$B$10)-'Debt'!$B$12,0) | M24: =IF(2<='Assumptions'!$B$8,('P&L'!$C$10*(1+M$20)^1+'Renovation'!C$18-'P&L'!$C$23*(1+'Assumptions'!$B$15)^1)-'Debt'!$B$9,0)+IF(2='Assumptions'!$B$8,('P&L'!$C$10*(1+M$20)^1+'Renovation'!C$18-'P&L'!$C$23*(1+'Assumptions'!$B$15)^1)/M$21*(1-'Assumptions'!$B$10)-'Debt'!$B$12,0) | N24: =IF(2<='Assumptions'!$B$8,('P&L'!$C$10*(1+N$20)^1+'Renovation'!C$18-'P&L'!$C$23*(1+'Assumptions'!$B$15)^1)-'Debt'!$B$9,0)+IF(2='Assumptions'!$B$8,('P&L'!$C$10*(1+N$20)^1+'Renovation'!C$18-'P&L'!$C$23*(1+'Assumptions'!$B$15)^1)/N$21*(1-'Assumptions'!$B$10)-'Debt'!$B$12,0) | O24: =IF(2<='Assumptions'!$B$8,('P&L'!$C$10*(1+O$20)^1+'Renovation'!C$18-'P&L'!$C$23*(1+'Assumptions'!$B$15)^1)-'Debt'!$B$9,0)+IF(2='Assumptions'!$B$8,('P&L'!$C$10*(1+O$20)^1+'Renovation'!C$18-'P&L'!$C$23*(1+'Assumptions'!$B$15)^1)/O$21*(1-'Assumptions'!$B$10)-'Debt'!$B$12,0) | P24: =IF(2<='Assumptions'!$B$8,('P&L'!$C$10*(1+P$20)^1+'Renovation'!C$18-'P&L'!$C$23*(1+'Assumptions'!$B$15)^1)-'Debt'!$B$9,0)+IF(2='Assumptions'!$B$8,('P&L'!$C$10*(1+P$20)^1+'Renovation'!C$18-'P&L'!$C$23*(1+'Assumptions'!$B$15)^1)/P$21*(1-'Assumptions'!$B$10)-'Debt'!$B$12,0) | Q24: =IF(2<='Assumptions'!$B$8,('P&L'!$C$10*(1+Q$20)^1+'Renovation'!C$18-'P&L'!$C$23*(1+'Assumptions'!$B$15)^1)-'Debt'!$B$9,0)+IF(2='Assumptions'!$B$8,('P&L'!$C$10*(1+Q$20)^1+'Renovation'!C$18-'P&L'!$C$23*(1+'Assumptions'!$B$15)^1)/Q$21*(1-'Assumptions'!$B$10)-'Debt'!$B$12,0) | R24: =IF(2<='Assumptions'!$B$8,('P&L'!$C$10*(1+R$20)^1+'Renovation'!C$18-'P&L'!$C$23*(1+'Assumptions'!$B$15)^1)-'Debt'!$B$9,0)+IF(2='Assumptions'!$B$8,('P&L'!$C$10*(1+R$20)^1+'Renovation'!C$18-'P&L'!$C$23*(1+'Assumptions'!$B$15)^1)/R$21*(1-'Assumptions'!$B$10)-'Debt'!$B$12,0) | S24: =IF(2<='Assumptions'!$B$8,('P&L'!$C$10*(1+S$20)^1+'Renovation'!C$18-'P&L'!$C$23*(1+'Assumptions'!$B$15)^1)-'Debt'!$B$9,0)+IF(2='Assumptions'!$B$8,('P&L'!$C$10*(1+S$20)^1+'Renovation'!C$18-'P&L'!$C$23*(1+'Assumptions'!$B$15)^1)/S$21*(1-'Assumptions'!$B$10)-'Debt'!$B$12,0) | T24: =IF(2<='Assumptions'!$B$8,('P&L'!$C$10*(1+T$20)^1+'Renovation'!C$18-'P&L'!$C$23*(1+'Assumptions'!$B$15)^1)-'Debt'!$B$9,0)+IF(2='Assumptions'!$B$8,('P&L'!$C$10*(1+T$20)^1+'Renovation'!C$18-'P&L'!$C$23*(1+'Assumptions'!$B$15)^1)/T$21*(1-'Assumptions'!$B$10)-'Debt'!$B$12,0) | U24: =IF(2<='Assumptions'!$B$8,('P&L'!$C$10*(1+U$20)^1+'Renovation'!C$18-'P&L'!$C$23*(1+'Assumptions'!$B$15)^1)-'Debt'!$B$9,0)+IF(2='Assumptions'!$B$8,('P&L'!$C$10*(1+U$20)^1+'Renovation'!C$18-'P&L'!$C$23*(1+'Assumptions'!$B$15)^1)/U$21*(1-'Assumptions'!$B$10)-'Debt'!$B$12,0) | V24: =IF(2<='Assumptions'!$B$8,('P&L'!$C$10*(1+V$20)^1+'Renovation'!C$18-'P&L'!$C$23*(1+'Assumptions'!$B$15)^1)-'Debt'!$B$9,0)+IF(2='Assumptions'!$B$8,('P&L'!$C$10*(1+V$20)^1+'Renovation'!C$18-'P&L'!$C$23*(1+'Assumptions'!$B$15)^1)/V$21*(1-'Assumptions'!$B$10)-'Debt'!$B$12,0) | W24: =IF(2<='Assumptions'!$B$8,('P&L'!$C$10*(1+W$20)^1+'Renovation'!C$18-'P&L'!$C$23*(1+'Assumptions'!$B$15)^1)-'Debt'!$B$9,0)+IF(2='Assumptions'!$B$8,('P&L'!$C$10*(1+W$20)^1+'Renovation'!C$18-'P&L'!$C$23*(1+'Assumptions'!$B$15)^1)/W$21*(1-'Assumptions'!$B$10)-'Debt'!$B$12,0) | X24: =IF(2<='Assumptions'!$B$8,('P&L'!$C$10*(1+X$20)^1+'Renovation'!C$18-'P&L'!$C$23*(1+'Assumptions'!$B$15)^1)-'Debt'!$B$9,0)+IF(2='Assumptions'!$B$8,('P&L'!$C$10*(1+X$20)^1+'Renovation'!C$18-'P&L'!$C$23*(1+'Assumptions'!$B$15)^1)/X$21*(1-'Assumptions'!$B$10)-'Debt'!$B$12,0) | Y24: =IF(2<='Assumptions'!$B$8,('P&L'!$C$10*(1+Y$20)^1+'Renovation'!C$18-'P&L'!$C$23*(1+'Assumptions'!$B$15)^1)-'Debt'!$B$9,0)+IF(2='Assumptions'!$B$8,('P&L'!$C$10*(1+Y$20)^1+'Renovation'!C$18-'P&L'!$C$23*(1+'Assumptions'!$B$15)^1)/Y$21*(1-'Assumptions'!$B$10)-'Debt'!$B$12,0) | Z24: =IF(2<='Assumptions'!$B$8,('P&L'!$C$10*(1+Z$20)^1+'Renovation'!C$18-'P&L'!$C$23*(1+'Assumptions'!$B$15)^1)-'Debt'!$B$9,0)+IF(2='Assumptions'!$B$8,('P&L'!$C$10*(1+Z$20)^1+'Renovation'!C$18-'P&L'!$C$23*(1+'Assumptions'!$B$15)^1)/Z$21*(1-'Assumptions'!$B$10)-'Debt'!$B$12,0)
A25: CF Year 3 | B25: =IF(3<='Assumptions'!$B$8,('P&L'!$C$10*(1+B$20)^2+'Renovation'!D$18-'P&L'!$C$23*(1+'Assumptions'!$B$15)^2)-'Debt'!$B$9,0)+IF(3='Assumptions'!$B$8,('P&L'!$C$10*(1+B$20)^2+'Renovation'!D$18-'P&L'!$C$23*(1+'Assumptions'!$B$15)^2)/B$21*(1-'Assumptions'!$B$10)-'Debt'!$B$12,0) | C25: =IF(3<='Assumptions'!$B$8,('P&L'!$C$10*(1+C$20)^2+'Renovation'!D$18-'P&L'!$C$23*(1+'Assumptions'!$B$15)^2)-'Debt'!$B$9,0)+IF(3='Assumptions'!$B$8,('P&L'!$C$10*(1+C$20)^2+'Renovation'!D$18-'P&L'!$C$23*(1+'Assumptions'!$B$15)^2)/C$21*(1-'Assumptions'!$B$10)-'Debt'!$B$12,0) | D25: =IF(3<='Assumptions'!$B$8,('P&L'!$C$10*(1+D$20)^2+'Renovation'!D$18-'P&L'!$C$23*(1+'Assumptions'!$B$15)^2)-'Debt'!$B$9,0)+IF(3='Assumptions'!$B$8,('P&L'!$C$10*(1+D$20)^2+'Renovation'!D$18-'P&L'!$C$23*(1+'Assumptions'!$B$15)^2)/D$21*(1-'Assumptions'!$B$10)-'Debt'!$B$12,0) | E25: =IF(3<='Assumptions'!$B$8,('P&L'!$C$10*(1+E$20)^2+'Renovation'!D$18-'P&L'!$C$23*(1+'Assumptions'!$B$15)^2)-'Debt'!$B$9,0)+IF(3='Assumptions'!$B$8,('P&L'!$C$10*(1+E$20)^2+'Renovation'!D$18-'P&L'!$C$23*(1+'Assumptions'!$B$15)^2)/E$21*(1-'Assumptions'!$B$10)-'Debt'!$B$12,0) | F25: =IF(3<='Assumptions'!$B$8,('P&L'!$C$10*(1+F$20)^2+'Renovation'!D$18-'P&L'!$C$23*(1+'Assumptions'!$B$15)^2)-'Debt'!$B$9,0)+IF(3='Assumptions'!$B$8,('P&L'!$C$10*(1+F$20)^2+'Renovation'!D$18-'P&L'!$C$23*(1+'Assumptions'!$B$15)^2)/F$21*(1-'Assumptions'!$B$10)-'Debt'!$B$12,0) | G25: =IF(3<='Assumptions'!$B$8,('P&L'!$C$10*(1+G$20)^2+'Renovation'!D$18-'P&L'!$C$23*(1+'Assumptions'!$B$15)^2)-'Debt'!$B$9,0)+IF(3='Assumptions'!$B$8,('P&L'!$C$10*(1+G$20)^2+'Renovation'!D$18-'P&L'!$C$23*(1+'Assumptions'!$B$15)^2)/G$21*(1-'Assumptions'!$B$10)-'Debt'!$B$12,0) | H25: =IF(3<='Assumptions'!$B$8,('P&L'!$C$10*(1+H$20)^2+'Renovation'!D$18-'P&L'!$C$23*(1+'Assumptions'!$B$15)^2)-'Debt'!$B$9,0)+IF(3='Assumptions'!$B$8,('P&L'!$C$10*(1+H$20)^2+'Renovation'!D$18-'P&L'!$C$23*(1+'Assumptions'!$B$15)^2)/H$21*(1-'Assumptions'!$B$10)-'Debt'!$B$12,0) | I25: =IF(3<='Assumptions'!$B$8,('P&L'!$C$10*(1+I$20)^2+'Renovation'!D$18-'P&L'!$C$23*(1+'Assumptions'!$B$15)^2)-'Debt'!$B$9,0)+IF(3='Assumptions'!$B$8,('P&L'!$C$10*(1+I$20)^2+'Renovation'!D$18-'P&L'!$C$23*(1+'Assumptions'!$B$15)^2)/I$21*(1-'Assumptions'!$B$10)-'Debt'!$B$12,0) | J25: =IF(3<='Assumptions'!$B$8,('P&L'!$C$10*(1+J$20)^2+'Renovation'!D$18-'P&L'!$C$23*(1+'Assumptions'!$B$15)^2)-'Debt'!$B$9,0)+IF(3='Assumptions'!$B$8,('P&L'!$C$10*(1+J$20)^2+'Renovation'!D$18-'P&L'!$C$23*(1+'Assumptions'!$B$15)^2)/J$21*(1-'Assumptions'!$B$10)-'Debt'!$B$12,0) | K25: =IF(3<='Assumptions'!$B$8,('P&L'!$C$10*(1+K$20)^2+'Renovation'!D$18-'P&L'!$C$23*(1+'Assumptions'!$B$15)^2)-'Debt'!$B$9,0)+IF(3='Assumptions'!$B$8,('P&L'!$C$10*(1+K$20)^2+'Renovation'!D$18-'P&L'!$C$23*(1+'Assumptions'!$B$15)^2)/K$21*(1-'Assumptions'!$B$10)-'Debt'!$B$12,0) | L25: =IF(3<='Assumptions'!$B$8,('P&L'!$C$10*(1+L$20)^2+'Renovation'!D$18-'P&L'!$C$23*(1+'Assumptions'!$B$15)^2)-'Debt'!$B$9,0)+IF(3='Assumptions'!$B$8,('P&L'!$C$10*(1+L$20)^2+'Renovation'!D$18-'P&L'!$C$23*(1+'Assumptions'!$B$15)^2)/L$21*(1-'Assumptions'!$B$10)-'Debt'!$B$12,0) | M25: =IF(3<='Assumptions'!$B$8,('P&L'!$C$10*(1+M$20)^2+'Renovation'!D$18-'P&L'!$C$23*(1+'Assumptions'!$B$15)^2)-'Debt'!$B$9,0)+IF(3='Assumptions'!$B$8,('P&L'!$C$10*(1+M$20)^2+'Renovation'!D$18-'P&L'!$C$23*(1+'Assumptions'!$B$15)^2)/M$21*(1-'Assumptions'!$B$10)-'Debt'!$B$12,0) | N25: =IF(3<='Assumptions'!$B$8,('P&L'!$C$10*(1+N$20)^2+'Renovation'!D$18-'P&L'!$C$23*(1+'Assumptions'!$B$15)^2)-'Debt'!$B$9,0)+IF(3='Assumptions'!$B$8,('P&L'!$C$10*(1+N$20)^2+'Renovation'!D$18-'P&L'!$C$23*(1+'Assumptions'!$B$15)^2)/N$21*(1-'Assumptions'!$B$10)-'Debt'!$B$12,0) | O25: =IF(3<='Assumptions'!$B$8,('P&L'!$C$10*(1+O$20)^2+'Renovation'!D$18-'P&L'!$C$23*(1+'Assumptions'!$B$15)^2)-'Debt'!$B$9,0)+IF(3='Assumptions'!$B$8,('P&L'!$C$10*(1+O$20)^2+'Renovation'!D$18-'P&L'!$C$23*(1+'Assumptions'!$B$15)^2)/O$21*(1-'Assumptions'!$B$10)-'Debt'!$B$12,0) | P25: =IF(3<='Assumptions'!$B$8,('P&L'!$C$10*(1+P$20)^2+'Renovation'!D$18-'P&L'!$C$23*(1+'Assumptions'!$B$15)^2)-'Debt'!$B$9,0)+IF(3='Assumptions'!$B$8,('P&L'!$C$10*(1+P$20)^2+'Renovation'!D$18-'P&L'!$C$23*(1+'Assumptions'!$B$15)^2)/P$21*(1-'Assumptions'!$B$10)-'Debt'!$B$12,0) | Q25: =IF(3<='Assumptions'!$B$8,('P&L'!$C$10*(1+Q$20)^2+'Renovation'!D$18-'P&L'!$C$23*(1+'Assumptions'!$B$15)^2)-'Debt'!$B$9,0)+IF(3='Assumptions'!$B$8,('P&L'!$C$10*(1+Q$20)^2+'Renovation'!D$18-'P&L'!$C$23*(1+'Assumptions'!$B$15)^2)/Q$21*(1-'Assumptions'!$B$10)-'Debt'!$B$12,0) | R25: =IF(3<='Assumptions'!$B$8,('P&L'!$C$10*(1+R$20)^2+'Renovation'!D$18-'P&L'!$C$23*(1+'Assumptions'!$B$15)^2)-'Debt'!$B$9,0)+IF(3='Assumptions'!$B$8,('P&L'!$C$10*(1+R$20)^2+'Renovation'!D$18-'P&L'!$C$23*(1+'Assumptions'!$B$15)^2)/R$21*(1-'Assumptions'!$B$10)-'Debt'!$B$12,0) | S25: =IF(3<='Assumptions'!$B$8,('P&L'!$C$10*(1+S$20)^2+'Renovation'!D$18-'P&L'!$C$23*(1+'Assumptions'!$B$15)^2)-'Debt'!$B$9,0)+IF(3='Assumptions'!$B$8,('P&L'!$C$10*(1+S$20)^2+'Renovation'!D$18-'P&L'!$C$23*(1+'Assumptions'!$B$15)^2)/S$21*(1-'Assumptions'!$B$10)-'Debt'!$B$12,0) | T25: =IF(3<='Assumptions'!$B$8,('P&L'!$C$10*(1+T$20)^2+'Renovation'!D$18-'P&L'!$C$23*(1+'Assumptions'!$B$15)^2)-'Debt'!$B$9,0)+IF(3='Assumptions'!$B$8,('P&L'!$C$10*(1+T$20)^2+'Renovation'!D$18-'P&L'!$C$23*(1+'Assumptions'!$B$15)^2)/T$21*(1-'Assumptions'!$B$10)-'Debt'!$B$12,0) | U25: =IF(3<='Assumptions'!$B$8,('P&L'!$C$10*(1+U$20)^2+'Renovation'!D$18-'P&L'!$C$23*(1+'Assumptions'!$B$15)^2)-'Debt'!$B$9,0)+IF(3='Assumptions'!$B$8,('P&L'!$C$10*(1+U$20)^2+'Renovation'!D$18-'P&L'!$C$23*(1+'Assumptions'!$B$15)^2)/U$21*(1-'Assumptions'!$B$10)-'Debt'!$B$12,0) | V25: =IF(3<='Assumptions'!$B$8,('P&L'!$C$10*(1+V$20)^2+'Renovation'!D$18-'P&L'!$C$23*(1+'Assumptions'!$B$15)^2)-'Debt'!$B$9,0)+IF(3='Assumptions'!$B$8,('P&L'!$C$10*(1+V$20)^2+'Renovation'!D$18-'P&L'!$C$23*(1+'Assumptions'!$B$15)^2)/V$21*(1-'Assumptions'!$B$10)-'Debt'!$B$12,0) | W25: =IF(3<='Assumptions'!$B$8,('P&L'!$C$10*(1+W$20)^2+'Renovation'!D$18-'P&L'!$C$23*(1+'Assumptions'!$B$15)^2)-'Debt'!$B$9,0)+IF(3='Assumptions'!$B$8,('P&L'!$C$10*(1+W$20)^2+'Renovation'!D$18-'P&L'!$C$23*(1+'Assumptions'!$B$15)^2)/W$21*(1-'Assumptions'!$B$10)-'Debt'!$B$12,0) | X25: =IF(3<='Assumptions'!$B$8,('P&L'!$C$10*(1+X$20)^2+'Renovation'!D$18-'P&L'!$C$23*(1+'Assumptions'!$B$15)^2)-'Debt'!$B$9,0)+IF(3='Assumptions'!$B$8,('P&L'!$C$10*(1+X$20)^2+'Renovation'!D$18-'P&L'!$C$23*(1+'Assumptions'!$B$15)^2)/X$21*(1-'Assumptions'!$B$10)-'Debt'!$B$12,0) | Y25: =IF(3<='Assumptions'!$B$8,('P&L'!$C$10*(1+Y$20)^2+'Renovation'!D$18-'P&L'!$C$23*(1+'Assumptions'!$B$15)^2)-'Debt'!$B$9,0)+IF(3='Assumptions'!$B$8,('P&L'!$C$10*(1+Y$20)^2+'Renovation'!D$18-'P&L'!$C$23*(1+'Assumptions'!$B$15)^2)/Y$21*(1-'Assumptions'!$B$10)-'Debt'!$B$12,0) | Z25: =IF(3<='Assumptions'!$B$8,('P&L'!$C$10*(1+Z$20)^2+'Renovation'!D$18-'P&L'!$C$23*(1+'Assumptions'!$B$15)^2)-'Debt'!$B$9,0)+IF(3='Assumptions'!$B$8,('P&L'!$C$10*(1+Z$20)^2+'Renovation'!D$18-'P&L'!$C$23*(1+'Assumptions'!$B$15)^2)/Z$21*(1-'Assumptions'!$B$10)-'Debt'!$B$12,0)
A26: CF Year 4 | B26: =IF(4<='Assumptions'!$B$8,('P&L'!$C$10*(1+B$20)^3+'Renovation'!E$18-'P&L'!$C$23*(1+'Assumptions'!$B$15)^3)-'Debt'!$B$9,0)+IF(4='Assumptions'!$B$8,('P&L'!$C$10*(1+B$20)^3+'Renovation'!E$18-'P&L'!$C$23*(1+'Assumptions'!$B$15)^3)/B$21*(1-'Assumptions'!$B$10)-'Debt'!$B$12,0) | C26: =IF(4<='Assumptions'!$B$8,('P&L'!$C$10*(1+C$20)^3+'Renovation'!E$18-'P&L'!$C$23*(1+'Assumptions'!$B$15)^3)-'Debt'!$B$9,0)+IF(4='Assumptions'!$B$8,('P&L'!$C$10*(1+C$20)^3+'Renovation'!E$18-'P&L'!$C$23*(1+'Assumptions'!$B$15)^3)/C$21*(1-'Assumptions'!$B$10)-'Debt'!$B$12,0) | D26: =IF(4<='Assumptions'!$B$8,('P&L'!$C$10*(1+D$20)^3+'Renovation'!E$18-'P&L'!$C$23*(1+'Assumptions'!$B$15)^3)-'Debt'!$B$9,0)+IF(4='Assumptions'!$B$8,('P&L'!$C$10*(1+D$20)^3+'Renovation'!E$18-'P&L'!$C$23*(1+'Assumptions'!$B$15)^3)/D$21*(1-'Assumptions'!$B$10)-'Debt'!$B$12,0) | E26: =IF(4<='Assumptions'!$B$8,('P&L'!$C$10*(1+E$20)^3+'Renovation'!E$18-'P&L'!$C$23*(1+'Assumptions'!$B$15)^3)-'Debt'!$B$9,0)+IF(4='Assumptions'!$B$8,('P&L'!$C$10*(1+E$20)^3+'Renovation'!E$18-'P&L'!$C$23*(1+'Assumptions'!$B$15)^3)/E$21*(1-'Assumptions'!$B$10)-'Debt'!$B$12,0) | F26: =IF(4<='Assumptions'!$B$8,('P&L'!$C$10*(1+F$20)^3+'Renovation'!E$18-'P&L'!$C$23*(1+'Assumptions'!$B$15)^3)-'Debt'!$B$9,0)+IF(4='Assumptions'!$B$8,('P&L'!$C$10*(1+F$20)^3+'Renovation'!E$18-'P&L'!$C$23*(1+'Assumptions'!$B$15)^3)/F$21*(1-'Assumptions'!$B$10)-'Debt'!$B$12,0) | G26: =IF(4<='Assumptions'!$B$8,('P&L'!$C$10*(1+G$20)^3+'Renovation'!E$18-'P&L'!$C$23*(1+'Assumptions'!$B$15)^3)-'Debt'!$B$9,0)+IF(4='Assumptions'!$B$8,('P&L'!$C$10*(1+G$20)^3+'Renovation'!E$18-'P&L'!$C$23*(1+'Assumptions'!$B$15)^3)/G$21*(1-'Assumptions'!$B$10)-'Debt'!$B$12,0) | H26: =IF(4<='Assumptions'!$B$8,('P&L'!$C$10*(1+H$20)^3+'Renovation'!E$18-'P&L'!$C$23*(1+'Assumptions'!$B$15)^3)-'Debt'!$B$9,0)+IF(4='Assumptions'!$B$8,('P&L'!$C$10*(1+H$20)^3+'Renovation'!E$18-'P&L'!$C$23*(1+'Assumptions'!$B$15)^3)/H$21*(1-'Assumptions'!$B$10)-'Debt'!$B$12,0) | I26: =IF(4<='Assumptions'!$B$8,('P&L'!$C$10*(1+I$20)^3+'Renovation'!E$18-'P&L'!$C$23*(1+'Assumptions'!$B$15)^3)-'Debt'!$B$9,0)+IF(4='Assumptions'!$B$8,('P&L'!$C$10*(1+I$20)^3+'Renovation'!E$18-'P&L'!$C$23*(1+'Assumptions'!$B$15)^3)/I$21*(1-'Assumptions'!$B$10)-'Debt'!$B$12,0) | J26: =IF(4<='Assumptions'!$B$8,('P&L'!$C$10*(1+J$20)^3+'Renovation'!E$18-'P&L'!$C$23*(1+'Assumptions'!$B$15)^3)-'Debt'!$B$9,0)+IF(4='Assumptions'!$B$8,('P&L'!$C$10*(1+J$20)^3+'Renovation'!E$18-'P&L'!$C$23*(1+'Assumptions'!$B$15)^3)/J$21*(1-'Assumptions'!$B$10)-'Debt'!$B$12,0) | K26: =IF(4<='Assumptions'!$B$8,('P&L'!$C$10*(1+K$20)^3+'Renovation'!E$18-'P&L'!$C$23*(1+'Assumptions'!$B$15)^3)-'Debt'!$B$9,0)+IF(4='Assumptions'!$B$8,('P&L'!$C$10*(1+K$20)^3+'Renovation'!E$18-'P&L'!$C$23*(1+'Assumptions'!$B$15)^3)/K$21*(1-'Assumptions'!$B$10)-'Debt'!$B$12,0) | L26: =IF(4<='Assumptions'!$B$8,('P&L'!$C$10*(1+L$20)^3+'Renovation'!E$18-'P&L'!$C$23*(1+'Assumptions'!$B$15)^3)-'Debt'!$B$9,0)+IF(4='Assumptions'!$B$8,('P&L'!$C$10*(1+L$20)^3+'Renovation'!E$18-'P&L'!$C$23*(1+'Assumptions'!$B$15)^3)/L$21*(1-'Assumptions'!$B$10)-'Debt'!$B$12,0) | M26: =IF(4<='Assumptions'!$B$8,('P&L'!$C$10*(1+M$20)^3+'Renovation'!E$18-'P&L'!$C$23*(1+'Assumptions'!$B$15)^3)-'Debt'!$B$9,0)+IF(4='Assumptions'!$B$8,('P&L'!$C$10*(1+M$20)^3+'Renovation'!E$18-'P&L'!$C$23*(1+'Assumptions'!$B$15)^3)/M$21*(1-'Assumptions'!$B$10)-'Debt'!$B$12,0) | N26: =IF(4<='Assumptions'!$B$8,('P&L'!$C$10*(1+N$20)^3+'Renovation'!E$18-'P&L'!$C$23*(1+'Assumptions'!$B$15)^3)-'Debt'!$B$9,0)+IF(4='Assumptions'!$B$8,('P&L'!$C$10*(1+N$20)^3+'Renovation'!E$18-'P&L'!$C$23*(1+'Assumptions'!$B$15)^3)/N$21*(1-'Assumptions'!$B$10)-'Debt'!$B$12,0) | O26: =IF(4<='Assumptions'!$B$8,('P&L'!$C$10*(1+O$20)^3+'Renovation'!E$18-'P&L'!$C$23*(1+'Assumptions'!$B$15)^3)-'Debt'!$B$9,0)+IF(4='Assumptions'!$B$8,('P&L'!$C$10*(1+O$20)^3+'Renovation'!E$18-'P&L'!$C$23*(1+'Assumptions'!$B$15)^3)/O$21*(1-'Assumptions'!$B$10)-'Debt'!$B$12,0) | P26: =IF(4<='Assumptions'!$B$8,('P&L'!$C$10*(1+P$20)^3+'Renovation'!E$18-'P&L'!$C$23*(1+'Assumptions'!$B$15)^3)-'Debt'!$B$9,0)+IF(4='Assumptions'!$B$8,('P&L'!$C$10*(1+P$20)^3+'Renovation'!E$18-'P&L'!$C$23*(1+'Assumptions'!$B$15)^3)/P$21*(1-'Assumptions'!$B$10)-'Debt'!$B$12,0) | Q26: =IF(4<='Assumptions'!$B$8,('P&L'!$C$10*(1+Q$20)^3+'Renovation'!E$18-'P&L'!$C$23*(1+'Assumptions'!$B$15)^3)-'Debt'!$B$9,0)+IF(4='Assumptions'!$B$8,('P&L'!$C$10*(1+Q$20)^3+'Renovation'!E$18-'P&L'!$C$23*(1+'Assumptions'!$B$15)^3)/Q$21*(1-'Assumptions'!$B$10)-'Debt'!$B$12,0) | R26: =IF(4<='Assumptions'!$B$8,('P&L'!$C$10*(1+R$20)^3+'Renovation'!E$18-'P&L'!$C$23*(1+'Assumptions'!$B$15)^3)-'Debt'!$B$9,0)+IF(4='Assumptions'!$B$8,('P&L'!$C$10*(1+R$20)^3+'Renovation'!E$18-'P&L'!$C$23*(1+'Assumptions'!$B$15)^3)/R$21*(1-'Assumptions'!$B$10)-'Debt'!$B$12,0) | S26: =IF(4<='Assumptions'!$B$8,('P&L'!$C$10*(1+S$20)^3+'Renovation'!E$18-'P&L'!$C$23*(1+'Assumptions'!$B$15)^3)-'Debt'!$B$9,0)+IF(4='Assumptions'!$B$8,('P&L'!$C$10*(1+S$20)^3+'Renovation'!E$18-'P&L'!$C$23*(1+'Assumptions'!$B$15)^3)/S$21*(1-'Assumptions'!$B$10)-'Debt'!$B$12,0) | T26: =IF(4<='Assumptions'!$B$8,('P&L'!$C$10*(1+T$20)^3+'Renovation'!E$18-'P&L'!$C$23*(1+'Assumptions'!$B$15)^3)-'Debt'!$B$9,0)+IF(4='Assumptions'!$B$8,('P&L'!$C$10*(1+T$20)^3+'Renovation'!E$18-'P&L'!$C$23*(1+'Assumptions'!$B$15)^3)/T$21*(1-'Assumptions'!$B$10)-'Debt'!$B$12,0) | U26: =IF(4<='Assumptions'!$B$8,('P&L'!$C$10*(1+U$20)^3+'Renovation'!E$18-'P&L'!$C$23*(1+'Assumptions'!$B$15)^3)-'Debt'!$B$9,0)+IF(4='Assumptions'!$B$8,('P&L'!$C$10*(1+U$20)^3+'Renovation'!E$18-'P&L'!$C$23*(1+'Assumptions'!$B$15)^3)/U$21*(1-'Assumptions'!$B$10)-'Debt'!$B$12,0) | V26: =IF(4<='Assumptions'!$B$8,('P&L'!$C$10*(1+V$20)^3+'Renovation'!E$18-'P&L'!$C$23*(1+'Assumptions'!$B$15)^3)-'Debt'!$B$9,0)+IF(4='Assumptions'!$B$8,('P&L'!$C$10*(1+V$20)^3+'Renovation'!E$18-'P&L'!$C$23*(1+'Assumptions'!$B$15)^3)/V$21*(1-'Assumptions'!$B$10)-'Debt'!$B$12,0) | W26: =IF(4<='Assumptions'!$B$8,('P&L'!$C$10*(1+W$20)^3+'Renovation'!E$18-'P&L'!$C$23*(1+'Assumptions'!$B$15)^3)-'Debt'!$B$9,0)+IF(4='Assumptions'!$B$8,('P&L'!$C$10*(1+W$20)^3+'Renovation'!E$18-'P&L'!$C$23*(1+'Assumptions'!$B$15)^3)/W$21*(1-'Assumptions'!$B$10)-'Debt'!$B$12,0) | X26: =IF(4<='Assumptions'!$B$8,('P&L'!$C$10*(1+X$20)^3+'Renovation'!E$18-'P&L'!$C$23*(1+'Assumptions'!$B$15)^3)-'Debt'!$B$9,0)+IF(4='Assumptions'!$B$8,('P&L'!$C$10*(1+X$20)^3+'Renovation'!E$18-'P&L'!$C$23*(1+'Assumptions'!$B$15)^3)/X$21*(1-'Assumptions'!$B$10)-'Debt'!$B$12,0) | Y26: =IF(4<='Assumptions'!$B$8,('P&L'!$C$10*(1+Y$20)^3+'Renovation'!E$18-'P&L'!$C$23*(1+'Assumptions'!$B$15)^3)-'Debt'!$B$9,0)+IF(4='Assumptions'!$B$8,('P&L'!$C$10*(1+Y$20)^3+'Renovation'!E$18-'P&L'!$C$23*(1+'Assumptions'!$B$15)^3)/Y$21*(1-'Assumptions'!$B$10)-'Debt'!$B$12,0) | Z26: =IF(4<='Assumptions'!$B$8,('P&L'!$C$10*(1+Z$20)^3+'Renovation'!E$18-'P&L'!$C$23*(1+'Assumptions'!$B$15)^3)-'Debt'!$B$9,0)+IF(4='Assumptions'!$B$8,('P&L'!$C$10*(1+Z$20)^3+'Renovation'!E$18-'P&L'!$C$23*(1+'Assumptions'!$B$15)^3)/Z$21*(1-'Assumptions'!$B$10)-'Debt'!$B$12,0)
A27: CF Year 5 | B27: =IF(5<='Assumptions'!$B$8,('P&L'!$C$10*(1+B$20)^4+'Renovation'!F$18-'P&L'!$C$23*(1+'Assumptions'!$B$15)^4)-'Debt'!$B$9,0)+IF(5='Assumptions'!$B$8,('P&L'!$C$10*(1+B$20)^4+'Renovation'!F$18-'P&L'!$C$23*(1+'Assumptions'!$B$15)^4)/B$21*(1-'Assumptions'!$B$10)-'Debt'!$B$12,0) | C27: =IF(5<='Assumptions'!$B$8,('P&L'!$C$10*(1+C$20)^4+'Renovation'!F$18-'P&L'!$C$23*(1+'Assumptions'!$B$15)^4)-'Debt'!$B$9,0)+IF(5='Assumptions'!$B$8,('P&L'!$C$10*(1+C$20)^4+'Renovation'!F$18-'P&L'!$C$23*(1+'Assumptions'!$B$15)^4)/C$21*(1-'Assumptions'!$B$10)-'Debt'!$B$12,0) | D27: =IF(5<='Assumptions'!$B$8,('P&L'!$C$10*(1+D$20)^4+'Renovation'!F$18-'P&L'!$C$23*(1+'Assumptions'!$B$15)^4)-'Debt'!$B$9,0)+IF(5='Assumptions'!$B$8,('P&L'!$C$10*(1+D$20)^4+'Renovation'!F$18-'P&L'!$C$23*(1+'Assumptions'!$B$15)^4)/D$21*(1-'Assumptions'!$B$10)-'Debt'!$B$12,0) | E27: =IF(5<='Assumptions'!$B$8,('P&L'!$C$10*(1+E$20)^4+'Renovation'!F$18-'P&L'!$C$23*(1+'Assumptions'!$B$15)^4)-'Debt'!$B$9,0)+IF(5='Assumptions'!$B$8,('P&L'!$C$10*(1+E$20)^4+'Renovation'!F$18-'P&L'!$C$23*(1+'Assumptions'!$B$15)^4)/E$21*(1-'Assumptions'!$B$10)-'Debt'!$B$12,0) | F27: =IF(5<='Assumptions'!$B$8,('P&L'!$C$10*(1+F$20)^4+'Renovation'!F$18-'P&L'!$C$23*(1+'Assumptions'!$B$15)^4)-'Debt'!$B$9,0)+IF(5='Assumptions'!$B$8,('P&L'!$C$10*(1+F$20)^4+'Renovation'!F$18-'P&L'!$C$23*(1+'Assumptions'!$B$15)^4)/F$21*(1-'Assumptions'!$B$10)-'Debt'!$B$12,0) | G27: =IF(5<='Assumptions'!$B$8,('P&L'!$C$10*(1+G$20)^4+'Renovation'!F$18-'P&L'!$C$23*(1+'Assumptions'!$B$15)^4)-'Debt'!$B$9,0)+IF(5='Assumptions'!$B$8,('P&L'!$C$10*(1+G$20)^4+'Renovation'!F$18-'P&L'!$C$23*(1+'Assumptions'!$B$15)^4)/G$21*(1-'Assumptions'!$B$10)-'Debt'!$B$12,0) | H27: =IF(5<='Assumptions'!$B$8,('P&L'!$C$10*(1+H$20)^4+'Renovation'!F$18-'P&L'!$C$23*(1+'Assumptions'!$B$15)^4)-'Debt'!$B$9,0)+IF(5='Assumptions'!$B$8,('P&L'!$C$10*(1+H$20)^4+'Renovation'!F$18-'P&L'!$C$23*(1+'Assumptions'!$B$15)^4)/H$21*(1-'Assumptions'!$B$10)-'Debt'!$B$12,0) | I27: =IF(5<='Assumptions'!$B$8,('P&L'!$C$10*(1+I$20)^4+'Renovation'!F$18-'P&L'!$C$23*(1+'Assumptions'!$B$15)^4)-'Debt'!$B$9,0)+IF(5='Assumptions'!$B$8,('P&L'!$C$10*(1+I$20)^4+'Renovation'!F$18-'P&L'!$C$23*(1+'Assumptions'!$B$15)^4)/I$21*(1-'Assumptions'!$B$10)-'Debt'!$B$12,0) | J27: =IF(5<='Assumptions'!$B$8,('P&L'!$C$10*(1+J$20)^4+'Renovation'!F$18-'P&L'!$C$23*(1+'Assumptions'!$B$15)^4)-'Debt'!$B$9,0)+IF(5='Assumptions'!$B$8,('P&L'!$C$10*(1+J$20)^4+'Renovation'!F$18-'P&L'!$C$23*(1+'Assumptions'!$B$15)^4)/J$21*(1-'Assumptions'!$B$10)-'Debt'!$B$12,0) | K27: =IF(5<='Assumptions'!$B$8,('P&L'!$C$10*(1+K$20)^4+'Renovation'!F$18-'P&L'!$C$23*(1+'Assumptions'!$B$15)^4)-'Debt'!$B$9,0)+IF(5='Assumptions'!$B$8,('P&L'!$C$10*(1+K$20)^4+'Renovation'!F$18-'P&L'!$C$23*(1+'Assumptions'!$B$15)^4)/K$21*(1-'Assumptions'!$B$10)-'Debt'!$B$12,0) | L27: =IF(5<='Assumptions'!$B$8,('P&L'!$C$10*(1+L$20)^4+'Renovation'!F$18-'P&L'!$C$23*(1+'Assumptions'!$B$15)^4)-'Debt'!$B$9,0)+IF(5='Assumptions'!$B$8,('P&L'!$C$10*(1+L$20)^4+'Renovation'!F$18-'P&L'!$C$23*(1+'Assumptions'!$B$15)^4)/L$21*(1-'Assumptions'!$B$10)-'Debt'!$B$12,0) | M27: =IF(5<='Assumptions'!$B$8,('P&L'!$C$10*(1+M$20)^4+'Renovation'!F$18-'P&L'!$C$23*(1+'Assumptions'!$B$15)^4)-'Debt'!$B$9,0)+IF(5='Assumptions'!$B$8,('P&L'!$C$10*(1+M$20)^4+'Renovation'!F$18-'P&L'!$C$23*(1+'Assumptions'!$B$15)^4)/M$21*(1-'Assumptions'!$B$10)-'Debt'!$B$12,0) | N27: =IF(5<='Assumptions'!$B$8,('P&L'!$C$10*(1+N$20)^4+'Renovation'!F$18-'P&L'!$C$23*(1+'Assumptions'!$B$15)^4)-'Debt'!$B$9,0)+IF(5='Assumptions'!$B$8,('P&L'!$C$10*(1+N$20)^4+'Renovation'!F$18-'P&L'!$C$23*(1+'Assumptions'!$B$15)^4)/N$21*(1-'Assumptions'!$B$10)-'Debt'!$B$12,0) | O27: =IF(5<='Assumptions'!$B$8,('P&L'!$C$10*(1+O$20)^4+'Renovation'!F$18-'P&L'!$C$23*(1+'Assumptions'!$B$15)^4)-'Debt'!$B$9,0)+IF(5='Assumptions'!$B$8,('P&L'!$C$10*(1+O$20)^4+'Renovation'!F$18-'P&L'!$C$23*(1+'Assumptions'!$B$15)^4)/O$21*(1-'Assumptions'!$B$10)-'Debt'!$B$12,0) | P27: =IF(5<='Assumptions'!$B$8,('P&L'!$C$10*(1+P$20)^4+'Renovation'!F$18-'P&L'!$C$23*(1+'Assumptions'!$B$15)^4)-'Debt'!$B$9,0)+IF(5='Assumptions'!$B$8,('P&L'!$C$10*(1+P$20)^4+'Renovation'!F$18-'P&L'!$C$23*(1+'Assumptions'!$B$15)^4)/P$21*(1-'Assumptions'!$B$10)-'Debt'!$B$12,0) | Q27: =IF(5<='Assumptions'!$B$8,('P&L'!$C$10*(1+Q$20)^4+'Renovation'!F$18-'P&L'!$C$23*(1+'Assumptions'!$B$15)^4)-'Debt'!$B$9,0)+IF(5='Assumptions'!$B$8,('P&L'!$C$10*(1+Q$20)^4+'Renovation'!F$18-'P&L'!$C$23*(1+'Assumptions'!$B$15)^4)/Q$21*(1-'Assumptions'!$B$10)-'Debt'!$B$12,0) | R27: =IF(5<='Assumptions'!$B$8,('P&L'!$C$10*(1+R$20)^4+'Renovation'!F$18-'P&L'!$C$23*(1+'Assumptions'!$B$15)^4)-'Debt'!$B$9,0)+IF(5='Assumptions'!$B$8,('P&L'!$C$10*(1+R$20)^4+'Renovation'!F$18-'P&L'!$C$23*(1+'Assumptions'!$B$15)^4)/R$21*(1-'Assumptions'!$B$10)-'Debt'!$B$12,0) | S27: =IF(5<='Assumptions'!$B$8,('P&L'!$C$10*(1+S$20)^4+'Renovation'!F$18-'P&L'!$C$23*(1+'Assumptions'!$B$15)^4)-'Debt'!$B$9,0)+IF(5='Assumptions'!$B$8,('P&L'!$C$10*(1+S$20)^4+'Renovation'!F$18-'P&L'!$C$23*(1+'Assumptions'!$B$15)^4)/S$21*(1-'Assumptions'!$B$10)-'Debt'!$B$12,0) | T27: =IF(5<='Assumptions'!$B$8,('P&L'!$C$10*(1+T$20)^4+'Renovation'!F$18-'P&L'!$C$23*(1+'Assumptions'!$B$15)^4)-'Debt'!$B$9,0)+IF(5='Assumptions'!$B$8,('P&L'!$C$10*(1+T$20)^4+'Renovation'!F$18-'P&L'!$C$23*(1+'Assumptions'!$B$15)^4)/T$21*(1-'Assumptions'!$B$10)-'Debt'!$B$12,0) | U27: =IF(5<='Assumptions'!$B$8,('P&L'!$C$10*(1+U$20)^4+'Renovation'!F$18-'P&L'!$C$23*(1+'Assumptions'!$B$15)^4)-'Debt'!$B$9,0)+IF(5='Assumptions'!$B$8,('P&L'!$C$10*(1+U$20)^4+'Renovation'!F$18-'P&L'!$C$23*(1+'Assumptions'!$B$15)^4)/U$21*(1-'Assumptions'!$B$10)-'Debt'!$B$12,0) | V27: =IF(5<='Assumptions'!$B$8,('P&L'!$C$10*(1+V$20)^4+'Renovation'!F$18-'P&L'!$C$23*(1+'Assumptions'!$B$15)^4)-'Debt'!$B$9,0)+IF(5='Assumptions'!$B$8,('P&L'!$C$10*(1+V$20)^4+'Renovation'!F$18-'P&L'!$C$23*(1+'Assumptions'!$B$15)^4)/V$21*(1-'Assumptions'!$B$10)-'Debt'!$B$12,0) | W27: =IF(5<='Assumptions'!$B$8,('P&L'!$C$10*(1+W$20)^4+'Renovation'!F$18-'P&L'!$C$23*(1+'Assumptions'!$B$15)^4)-'Debt'!$B$9,0)+IF(5='Assumptions'!$B$8,('P&L'!$C$10*(1+W$20)^4+'Renovation'!F$18-'P&L'!$C$23*(1+'Assumptions'!$B$15)^4)/W$21*(1-'Assumptions'!$B$10)-'Debt'!$B$12,0) | X27: =IF(5<='Assumptions'!$B$8,('P&L'!$C$10*(1+X$20)^4+'Renovation'!F$18-'P&L'!$C$23*(1+'Assumptions'!$B$15)^4)-'Debt'!$B$9,0)+IF(5='Assumptions'!$B$8,('P&L'!$C$10*(1+X$20)^4+'Renovation'!F$18-'P&L'!$C$23*(1+'Assumptions'!$B$15)^4)/X$21*(1-'Assumptions'!$B$10)-'Debt'!$B$12,0) | Y27: =IF(5<='Assumptions'!$B$8,('P&L'!$C$10*(1+Y$20)^4+'Renovation'!F$18-'P&L'!$C$23*(1+'Assumptions'!$B$15)^4)-'Debt'!$B$9,0)+IF(5='Assumptions'!$B$8,('P&L'!$C$10*(1+Y$20)^4+'Renovation'!F$18-'P&L'!$C$23*(1+'Assumptions'!$B$15)^4)/Y$21*(1-'Assumptions'!$B$10)-'Debt'!$B$12,0) | Z27: =IF(5<='Assumptions'!$B$8,('P&L'!$C$10*(1+Z$20)^4+'Renovation'!F$18-'P&L'!$C$23*(1+'Assumptions'!$B$15)^4)-'Debt'!$B$9,0)+IF(5='Assumptions'!$B$8,('P&L'!$C$10*(1+Z$20)^4+'Renovation'!F$18-'P&L'!$C$23*(1+'Assumptions'!$B$15)^4)/Z$21*(1-'Assumptions'!$B$10)-'Debt'!$B$12,0)
